Workbook

Sheet Source
C1: . | W1: 1.2 | X1: 1.2 | Z1: 1.2 | AD1: D IN STORE ITEMS | AI1: Single Unit Amounts | AR1: Margins | BB1: Final Margin Including Rebate | BG1: Item UPC | BH1: Case UPC | BJ1: Flyer Description | BK1: Story | BM1: Mainframe Description | BN1: Size | BO1: MS
A2: Item No. | B2: Item Details | C2: Minor Category | D2: CLMS | E2: Ad Code | F2: Ad Location Code | G2: Feature & Insert Code | H2: Limit | I2: Region | J2: Supplier Case Cost | K2: OI | L2: chq | M2: crc | N2: Count Recount By Inner | O2: Special Net Price | P2: Special Unit Price | Q2: ho | R2: Scan Back | S2: Scan Back / Unit | T2: Ad SRP | W2: AAA | X2: Yukon | Z2: A | AA2: Store % GP Rate | AC2: AAA | AD2: Yukon | AE2: AAA/AA | AF2: A | AH2: AAA | AI2: Yukon | AJ2: AAA/AA | AK2: A | AM2: NON EDBV Base Cost | AN2: Case Weight | AO2: Case Pack | AP2: Invoice Cost | AQ2: EDBV | AR2: AAA | AS2: Yukon | AT2: AAA/AA | AU2: A | BB2: AAA | BC2: Yukon | BD2: AAA/AA | BE2: A | BI2: 1 file notes | BP2: canada | BQ2: 13 | BR2: 14 | BS2: SNS | BT2: $ | BU2: kraft | BV2: nestle | BW2: mccormick | BX2: hq 2/9/26 | BY2: hq 3/3/26 | CA2: ho | CB2: 2 File notes | CC2: 1280 3/16/26 | CE2: ad code | CF2: cost | CG2: oi | CH2: chq | CI2: crc | CJ2: cost | CK2: oi | CL2: chq | CM2: crc | CN2: notes | CO2: srp | CP2: Ad SRP-old | CQ2: diff
A3: 780353 | B3: C-GOLD MILK CHOC VAN BAR 8 X 5 EA | C3: 010518110105 | D3: L M S | E3: A | F3: F | G3: F | I3: ALL | J3: 41.27 | O3: 41.27 | P3: 5.15875 | Q3: 2 | T3: 1 / $4.99 | U3: 1 | V3: $4.99 | W3: 1 /4.99 | X3: 5.99 | Z3: 5.49 | AA3: 0.030395541 | AC3: 5.99 | AD3: 7.19 | AE3: 6.19 | AF3: 7.19 | AH3: =IF(W3<>"",(RIGHT(W3,LEN(W3)-SEARCH("/",W3,1)))/U3,"") -> 4.99 | AI3: =IF(X3<>"",X3,"") -> 5.99 | AJ3: =IF(Y3<>"",Y3,"") | AK3: =IF(Z3<>"",Z3,"") -> 5.49 | AM3: 41.74 | AN3: 7.6 | AO3: 8 | AP3: =(AM3 * 1.05) - L3 - Q3 - K3 -> 41.827 | AQ3: N | AR3: =(((AH3)-((AP3/AO3) + ((AN3 * 0.03)/AO3)))/AH3)*100 -> -5.3481964 | AS3: =(((AI3)-((AP3/AO3) + ((AN3 * 0.3)/AO3)))/AI3)*100 -> 7.9570117 | AT3: =(((AJ3)-((AP3/AO3) + ((AN3 * 0.03)/AO3)))/AJ3)*100 -> #VALUE! | AU3: =(((AK3)-((AP3/AO3) + ((AN3 * 0.07)/AO3)))/AK3)*100 -> 3.5541894 | BB3: =(((AH3)-(((AP3/AO3) + ((AN3 * 0.03)/AO3))-AW3))/AH3)*100 -> -5.3481964 | BC3: =(((AI3)-(((AP3/AO3) + ((AN3 * 0.3)/AO3))-AX3))/AI3)*100 -> 7.9570117 | BD3: =(((AJ3)-(((AP3/AO3) + ((AN3 * 0.03)/AO3))-AY3))/AJ3)*100 -> #VALUE! | BE3: =(((AK3)-(((AP3/AO3) + ((AN3 * 0.15)/AO3))-AZ3))/AK3)*100 -> 2.1698543 | BG3: 0005731613224 | BH3: 0057316132243 | BJ3: Co-op Gold Ice Cream or Frozen Yogurt 1.5 L or Novelties Package of 4 - 12 | BM3: C-GOLD MILK CHOC VAN BAR | BN3: 5 | BO3: EA | BP3: 780353 | BQ3: #N/A | BR3: DNK | BS3: 22 | BT3: 16622.27 | BX3: 8.29 | BY3: 8.29 | BZ3: =BY3-BX3 -> 0 | CC3: =VLOOKUP(A3,'[1]RPT 1280 - Edmonton'!$1:$1048576,4,0) -> #N/A | CE3: EA | CF3: 41.27 | CG3: 0 | CH3: 0 | CI3: 0 | CJ3: =CF3-J3 -> 0 | CK3: =CG3-K3 -> 0 | CL3: =CH3-L3 -> 0 | CM3: =CI3-M3 -> 0 | CO3: 4.99 | CP3: 4.99 | CQ3: =CP3-CO3 -> 0
A4: 780312 | B4: C.GOLD CHC ALMD I/CRM BAR 8 X 5 EA | C4: 010518110105 | D4: L M S | E4: A | F4: F | G4: F | J4: =J3 -> 41.27 | O4: =O3 -> 41.27 | P4: =P3 -> 5.15875 | Q4: 2 | W4: 1 /4.99 | X4: 5.99 | Z4: 5.49 | AH4: =IF(W4<>"",(RIGHT(W4,LEN(W4)-SEARCH("/",W4,1)))/U4,"") -> #VALUE! | AI4: =IF(X4<>"",X4,"") -> 5.99 | AJ4: =IF(Y4<>"",Y4,"") | AK4: =IF(Z4<>"",Z4,"") -> 5.49 | BG4: 0005731613225 | BH4: 0057316132250 | BJ4: Co-op Gold Ice Cream or Frozen Yogurt 1.5 L or Novelties Package of 4 - 12 | BM4: C.GOLD CHC ALMD I/CRM BAR | BN4: 5 | BO4: EA | BP4: 780312 | BQ4: #N/A | BR4: DNK | BS4: 14 | BT4: 24284.54 | BX4: 8.29 | BY4: 8.29 | BZ4: =BY4-BX4 -> 0 | CC4: =VLOOKUP(A4,'[1]RPT 1280 - Edmonton'!$1:$1048576,4,0) -> #N/A | CE4: EA | CF4: 41.27 | CG4: 0 | CH4: 0 | CI4: 0 | CJ4: =CF4-J4 -> 0 | CK4: =CG4-K4 -> 0 | CL4: =CH4-L4 -> 0 | CM4: =CI4-M4 -> 0
A5: 780288 | B5: C.GOLD DARK CHC I/CRM BAR 8 X 5 EA | C5: 010518110105 | D5: L M S | E5: A | F5: F | G5: F | J5: =J4 -> 41.27 | O5: =O4 -> 41.27 | P5: =P4 -> 5.15875 | Q5: 2 | W5: 1 /4.99 | X5: 5.99 | Z5: 5.49 | AH5: =IF(W5<>"",(RIGHT(W5,LEN(W5)-SEARCH("/",W5,1)))/U5,"") -> #VALUE! | AI5: =IF(X5<>"",X5,"") -> 5.99 | AJ5: =IF(Y5<>"",Y5,"") | AK5: =IF(Z5<>"",Z5,"") -> 5.49 | BG5: 0005731613226 | BH5: 0057316132267 | BJ5: Co-op Gold Ice Cream or Frozen Yogurt 1.5 L or Novelties Package of 4 - 12 | BM5: C.GOLD DARK CHC I/CRM BAR | BN5: 5 | BO5: EA | BP5: 780288 | BQ5: #N/A | BR5: DNK | BS5: 28 | BT5: 10886.76 | BX5: 8.29 | BY5: 8.29 | BZ5: =BY5-BX5 -> 0 | CC5: =VLOOKUP(A5,'[1]RPT 1280 - Edmonton'!$1:$1048576,4,0) -> #N/A | CE5: EA | CF5: 41.27 | CG5: 0 | CH5: 0 | CI5: 0 | CJ5: =CF5-J5 -> 0 | CK5: =CG5-K5 -> 0 | CL5: =CH5-L5 -> 0 | CM5: =CI5-M5 -> 0
A6: 6399646 | B6: C.GOLD BEACH PARTY IC/CRM -Z 4 X 1.5 LT | C6: 010513110105 | D6: L M S | E6: A | F6: F | G6: F | I6: ALL | J6: 20.41 | O6: 20.41 | P6: 5.1025 | Q6: 4 | T6: 1 / $4.99 | U6: 1 | V6: $4.99 | W6: 1 /4.99 | X6: 5.99 | Z6: 5.49 | AA6: 0.028796092 | AC6: 5.99 | AD6: 7.19 | AE6: 6.19 | AF6: 7.19 | AH6: =IF(W6<>"",(RIGHT(W6,LEN(W6)-SEARCH("/",W6,1)))/U6,"") -> 4.99 | AI6: =IF(X6<>"",X6,"") -> 5.99 | AJ6: =IF(Y6<>"",Y6,"") | AK6: =IF(Z6<>"",Z6,"") -> 5.49 | AM6: 22 | AN6: 9.7 | AO6: 4 | AP6: =(AM6 * 1.05) - L6 - Q6 - K6 -> 19.1 | AQ6: N | AR6: =(((AH6)-((AP6/AO6) + ((AN6 * 0.03)/AO6)))/AH6)*100 -> 2.8507014 | AS6: =(((AI6)-((AP6/AO6) + ((AN6 * 0.3)/AO6)))/AI6)*100 -> 8.1385643 | AT6: =(((AJ6)-((AP6/AO6) + ((AN6 * 0.03)/AO6)))/AJ6)*100 -> #VALUE! | AU6: =(((AK6)-((AP6/AO6) + ((AN6 * 0.07)/AO6)))/AK6)*100 -> 9.931694 | BB6: =(((AH6)-(((AP6/AO6) + ((AN6 * 0.03)/AO6))-AW6))/AH6)*100 -> 2.8507014 | BC6: =(((AI6)-(((AP6/AO6) + ((AN6 * 0.3)/AO6))-AX6))/AI6)*100 -> 8.1385643 | BD6: =(((AJ6)-(((AP6/AO6) + ((AN6 * 0.03)/AO6))-AY6))/AJ6)*100 -> #VALUE! | BE6: =(((AK6)-(((AP6/AO6) + ((AN6 * 0.15)/AO6))-AZ6))/AK6)*100 -> 6.3979964 | BG6: 0005731621052 | BH6: 0057316210521 | BJ6: Co-op Gold Ice Cream or Frozen Yogurt 1.5 L or Novelties Package of 4 - 12 | BM6: C.GOLD BEACH PARTY IC/CRM -Z | BN6: 1.5 | BO6: LT | BP6: 6399646 | BQ6: #N/A | BR6: DNK | BS6: 26 | BT6: 3667.66 | BX6: 7.19 | BY6: 7.19 | BZ6: =BY6-BX6 -> 0 | CC6: =VLOOKUP(A6,'[1]RPT 1280 - Edmonton'!$1:$1048576,4,0) -> #N/A | CE6: EA | CF6: 20.41 | CG6: 0 | CH6: 0 | CI6: 0 | CJ6: =CF6-J6 -> 0 | CK6: =CG6-K6 -> 0 | CL6: =CH6-L6 -> 0 | CM6: =CI6-M6 -> 0 | CO6: 4.99 | CP6: 4.99 | CQ6: =CP6-CO6 -> 0
A7: 6442164 | B7: CG COOKIE DOUGH I/C BAR -Z 8 X 5 EA | C7: 010518110117 | D7: L M S | E7: A | F7: F | G7: F | I7: ALL | J7: 42.84 | O7: 42.84 | P7: 5.355 | Q7: 3 | T7: 1 / $4.99 | U7: 1 | V7: $4.99 | W7: 1 /4.99 | X7: 5.99 | Z7: 5.49 | AA7: 0.02907515 | AC7: 5.99 | AD7: 7.19 | AE7: 6.19 | AF7: 7.19 | AH7: =IF(W7<>"",(RIGHT(W7,LEN(W7)-SEARCH("/",W7,1)))/U7,"") -> 4.99 | AI7: =IF(X7<>"",X7,"") -> 5.99 | AJ7: =IF(Y7<>"",Y7,"") | AK7: =IF(Z7<>"",Z7,"") -> 5.49 | AM7: 43.45 | AN7: 5.29 | AO7: 8 | AP7: =(AM7 * 1.05) - L7 - Q7 - K7 -> 42.6225 | AQ7: N | AR7: =(((AH7)-((AP7/AO7) + ((AN7 * 0.03)/AO7)))/AH7)*100 -> -7.1673347 | AS7: =(((AI7)-((AP7/AO7) + ((AN7 * 0.3)/AO7)))/AI7)*100 -> 7.7431135 | AT7: =(((AJ7)-((AP7/AO7) + ((AN7 * 0.03)/AO7)))/AJ7)*100 -> #VALUE! | AU7: =(((AK7)-((AP7/AO7) + ((AN7 * 0.07)/AO7)))/AK7)*100 -> 2.1111111 | BB7: =(((AH7)-(((AP7/AO7) + ((AN7 * 0.03)/AO7))-AW7))/AH7)*100 -> -7.1673347 | BC7: =(((AI7)-(((AP7/AO7) + ((AN7 * 0.3)/AO7))-AX7))/AI7)*100 -> 7.7431135 | BD7: =(((AJ7)-(((AP7/AO7) + ((AN7 * 0.03)/AO7))-AY7))/AJ7)*100 -> #VALUE! | BE7: =(((AK7)-(((AP7/AO7) + ((AN7 * 0.15)/AO7))-AZ7))/AK7)*100 -> 1.147541 | BG7: 0005731621255 | BH7: 0057316212556 | BI7: 6524854 | BJ7: Co-op Gold Ice Cream or Frozen Yogurt 1.5 L or Novelties Package of 4 - 12 | BM7: CG COOKIE DOUGH I/C BAR -Z | BN7: 5 | BO7: EA | BP7: 6442164 | BQ7: #N/A | BR7: DNK | BS7: 51 | BT7: 593.02 | BX7: 8.79 | BY7: 8.79 | BZ7: =BY7-BX7 -> 0 | CB7: should these be keyed into ad - pk chnge-no they don’t have stop buys | CC7: =VLOOKUP(A7,'[1]RPT 1280 - Edmonton'!$1:$1048576,4,0) -> #N/A | CE7: EA | CF7: 42.84 | CG7: 0 | CH7: 0 | CI7: 0 | CJ7: =CF7-J7 -> 0 | CK7: =CG7-K7 -> 0 | CL7: =CH7-L7 -> 0 | CM7: =CI7-M7 -> 0 | CO7: 4.99 | CP7: 4.99 | CQ7: =CP7-CO7 -> 0
A8: 6442156 | B8: CG STWBRY CHSCAKE I/C BAR -Z 8 X 5 EA | C8: 010518110117 | D8: L M S | E8: A | F8: F | G8: F | J8: =J7 -> 42.84 | O8: =O7 -> 42.84 | P8: =P7 -> 5.355 | Q8: 3 | W8: 1 /4.99 | X8: 5.99 | Z8: 5.49 | AH8: =IF(W8<>"",(RIGHT(W8,LEN(W8)-SEARCH("/",W8,1)))/U8,"") -> #VALUE! | AI8: =IF(X8<>"",X8,"") -> 5.99 | AJ8: =IF(Y8<>"",Y8,"") | AK8: =IF(Z8<>"",Z8,"") -> 5.49 | BG8: 0005731621254 | BH8: 0057316212549 | BI8: 6524847-notyet they don’t have stop buys | BM8: CG STWBRY CHSCAKE I/C BAR -Z | BN8: 5 | BO8: EA | BP8: 6442156 | BQ8: #N/A | BR8: DNK | BS8: 50 | BT8: 989.96 | BX8: 8.79 | BY8: 8.79 | BZ8: =BY8-BX8 -> 0 | CC8: =VLOOKUP(A8,'[1]RPT 1280 - Edmonton'!$1:$1048576,4,0) -> #N/A | CE8: EA | CF8: 42.84 | CG8: 0 | CH8: 0 | CI8: 0 | CJ8: =CF8-J8 -> 0 | CK8: =CG8-K8 -> 0 | CL8: =CH8-L8 -> 0 | CM8: =CI8-M8 -> 0
A9: 6499271 | B9: CG OLD FASHIONED VAN I/C -NEW 4 X 1.5 LT | C9: 010513110100 | D9: L M S | E9: A | F9: F | G9: F | I9: ALL | J9: 21.14 | O9: 21.14 | P9: 5.285 | Q9: 3.2 | T9: 1 / $4.99 | U9: 1 | V9: $4.99 | W9: 1 /4.99 | X9: 5.99 | Z9: 5.49 | AA9: 0.028210421 | AC9: 5.99 | AD9: 7.19 | AE9: 6.19 | AF9: 7.19 | AH9: =IF(W9<>"",(RIGHT(W9,LEN(W9)-SEARCH("/",W9,1)))/U9,"") -> 4.99 | AI9: =IF(X9<>"",X9,"") -> 5.99 | AJ9: =IF(Y9<>"",Y9,"") | AK9: =IF(Z9<>"",Z9,"") -> 5.49 | AM9: 22.64 | AN9: 8.84 | AO9: 4 | AP9: =(AM9 * 1.05) - L9 - Q9 - K9 -> 20.572 | AQ9: N | AR9: =(((AH9)-((AP9/AO9) + ((AN9 * 0.03)/AO9)))/AH9)*100 -> -4.3947896 | AS9: =(((AI9)-((AP9/AO9) + ((AN9 * 0.3)/AO9)))/AI9)*100 -> 3.0717863 | AT9: =(((AJ9)-((AP9/AO9) + ((AN9 * 0.03)/AO9)))/AJ9)*100 -> #VALUE! | AU9: =(((AK9)-((AP9/AO9) + ((AN9 * 0.07)/AO9)))/AK9)*100 -> 3.5027322 | BB9: =(((AH9)-(((AP9/AO9) + ((AN9 * 0.03)/AO9))-AW9))/AH9)*100 -> -4.3947896 | BC9: =(((AI9)-(((AP9/AO9) + ((AN9 * 0.3)/AO9))-AX9))/AI9)*100 -> 3.0717863 | BD9: =(((AJ9)-(((AP9/AO9) + ((AN9 * 0.03)/AO9))-AY9))/AJ9)*100 -> #VALUE! | BE9: =(((AK9)-(((AP9/AO9) + ((AN9 * 0.15)/AO9))-AZ9))/AK9)*100 -> 0.28233151 | BG9: 0005731621715 | BH9: 0057316217155 | BJ9: Co-op Gold Ice Cream or Frozen Yogurt 1.5 L or Novelties Package of 4 - 12 | BM9: CG OLD FASHIONED VAN I/C -NEW | BN9: 1.5 | BO9: LT | BQ9: #N/A | BR9: DNK | BS9: 7 | BT9: 10924.05 | BX9: 7.19 | BY9: 7.19 | BZ9: =BY9-BX9 -> 0 | CC9: =VLOOKUP(A9,'[1]RPT 1280 - Edmonton'!$1:$1048576,4,0) -> #N/A | CE9: EA | CF9: 21.14 | CG9: 0 | CH9: 0 | CI9: 0 | CJ9: =CF9-J9 -> 0 | CK9: =CG9-K9 -> 0 | CL9: =CH9-L9 -> 0 | CM9: =CI9-M9 -> 0 | CO9: 4.99 | CP9: 4.99 | CQ9: =CP9-CO9 -> 0
A10: 6500722 | B10: CG BLK CHERRY FROZ YOGURT -NEW 4 X 1.5 LT | C10: 010513110100 | D10: L M S | E10: A | F10: F | G10: F | J10: =J9 -> 21.14 | O10: =O9 -> 21.14 | P10: =P9 -> 5.285 | Q10: 3 | W10: 1 /4.99 | X10: 5.99 | Z10: 5.49 | AH10: =IF(W10<>"",(RIGHT(W10,LEN(W10)-SEARCH("/",W10,1)))/U10,"") -> #VALUE! | AI10: =IF(X10<>"",X10,"") -> 5.99 | AJ10: =IF(Y10<>"",Y10,"") | AK10: =IF(Z10<>"",Z10,"") -> 5.49 | BG10: 0005731621747 | BH10: 0057316217476 | BJ10: Co-op Gold Ice Cream or Frozen Yogurt 1.5 L or Novelties Package of 4 - 12 | BM10: CG BLK CHERRY FROZ YOGURT -NEW | BN10: 1.5 | BO10: LT | BQ10: #N/A | BR10: DNK | BS10: 39 | BT10: 910.07 | BX10: 7.19 | BY10: 7.19 | BZ10: =BY10-BX10 -> 0 | CC10: =VLOOKUP(A10,'[1]RPT 1280 - Edmonton'!$1:$1048576,4,0) -> #N/A | CE10: EA | CF10: 21.14 | CG10: 0 | CH10: 0 | CI10: 0 | CJ10: =CF10-J10 -> 0 | CK10: =CG10-K10 -> 0 | CL10: =CH10-L10 -> 0 | CM10: =CI10-M10 -> 0
A11: 6500565 | B11: CG FUDGE SUNDAE SPRME I/C -NEW 4 X 1.5 LT | C11: 010513110100 | D11: L M S | E11: A | F11: F | G11: F | J11: =J10 -> 21.14 | O11: =O10 -> 21.14 | P11: =P10 -> 5.285 | Q11: 3.2 | W11: 1 /4.99 | X11: 5.99 | Z11: 5.49 | AH11: =IF(W11<>"",(RIGHT(W11,LEN(W11)-SEARCH("/",W11,1)))/U11,"") -> #VALUE! | AI11: =IF(X11<>"",X11,"") -> 5.99 | AJ11: =IF(Y11<>"",Y11,"") | AK11: =IF(Z11<>"",Z11,"") -> 5.49 | BG11: 0005731621718 | BH11: 0057316217186 | BM11: CG FUDGE SUNDAE SPRME I/C -NEW | BN11: 1.5 | BO11: LT | BQ11: #N/A | BR11: DNK | BS11: 25 | BT11: 3553.88 | BX11: 7.19 | BY11: 7.19 | BZ11: =BY11-BX11 -> 0 | CC11: =VLOOKUP(A11,'[1]RPT 1280 - Edmonton'!$1:$1048576,4,0) -> #N/A | CE11: EA | CF11: 21.14 | CG11: 0 | CH11: 0 | CI11: 0 | CJ11: =CF11-J11 -> 0 | CK11: =CG11-K11 -> 0 | CL11: =CH11-L11 -> 0 | CM11: =CI11-M11 -> 0
A12: 6500557 | B12: CG MAPLE WALNUT ICE CREAM -NEW 4 X 1.5 LT | C12: 010513110100 | D12: L M S | E12: A | F12: F | G12: F | J12: =J11 -> 21.14 | O12: =O11 -> 21.14 | P12: =P11 -> 5.285 | Q12: 3.2 | W12: 1 /4.99 | X12: 5.99 | Z12: 5.49 | AH12: =IF(W12<>"",(RIGHT(W12,LEN(W12)-SEARCH("/",W12,1)))/U12,"") -> #VALUE! | AI12: =IF(X12<>"",X12,"") -> 5.99 | AJ12: =IF(Y12<>"",Y12,"") | AK12: =IF(Z12<>"",Z12,"") -> 5.49 | BG12: 0005731621717 | BH12: 0057316217179 | BM12: CG MAPLE WALNUT ICE CREAM -NEW | BN12: 1.5 | BO12: LT | BQ12: #N/A | BR12: DNK | BS12: 16 | BT12: 3737.35 | BX12: 7.19 | BY12: 7.19 | BZ12: =BY12-BX12 -> 0 | CC12: =VLOOKUP(A12,'[1]RPT 1280 - Edmonton'!$1:$1048576,4,0) -> #N/A | CE12: EA | CF12: 21.14 | CG12: 0 | CH12: 0 | CI12: 0 | CJ12: =CF12-J12 -> 0 | CK12: =CG12-K12 -> 0 | CL12: =CH12-L12 -> 0 | CM12: =CI12-M12 -> 0
A13: 6500532 | B13: CG CHOC PEANUT BUTTER I/C -NEW 4 X 1.5 LT | C13: 010513110100 | D13: L M S | E13: A | F13: F | G13: F | J13: =J12 -> 21.14 | O13: =O12 -> 21.14 | P13: =P12 -> 5.285 | Q13: 3 | W13: 1 /4.99 | X13: 5.99 | Z13: 5.49 | AH13: =IF(W13<>"",(RIGHT(W13,LEN(W13)-SEARCH("/",W13,1)))/U13,"") -> #VALUE! | AI13: =IF(X13<>"",X13,"") -> 5.99 | AJ13: =IF(Y13<>"",Y13,"") | AK13: =IF(Z13<>"",Z13,"") -> 5.49 | BG13: 0005731621716 | BH13: 0057316217162 | BJ13: Co-op Gold Ice Cream or Frozen Yogurt 1.5 L or Novelties Package of 4 - 12 | BM13: CG CHOC PEANUT BUTTER I/C -NEW | BN13: 1.5 | BO13: LT | BQ13: #N/A | BR13: DNK | BS13: 14 | BT13: 10589.59 | BX13: 7.19 | BY13: 7.19 | BZ13: =BY13-BX13 -> 0 | CC13: =VLOOKUP(A13,'[1]RPT 1280 - Edmonton'!$1:$1048576,4,0) -> #N/A | CE13: EA | CF13: 21.14 | CG13: 0 | CH13: 0 | CI13: 0 | CJ13: =CF13-J13 -> 0 | CK13: =CG13-K13 -> 0 | CL13: =CH13-L13 -> 0 | CM13: =CI13-M13 -> 0
A14: 6500649 | B14: CG STRWBRRIES & CREME I/C -NEW 4 X 1.5 LT | C14: 010513110100 | D14: L M S | E14: A | F14: F | G14: F | J14: =J13 -> 21.14 | O14: =O13 -> 21.14 | P14: =P13 -> 5.285 | Q14: 3 | W14: 1 /4.99 | X14: 5.99 | Z14: 5.49 | AH14: =IF(W14<>"",(RIGHT(W14,LEN(W14)-SEARCH("/",W14,1)))/U14,"") -> #VALUE! | AI14: =IF(X14<>"",X14,"") -> 5.99 | AJ14: =IF(Y14<>"",Y14,"") | AK14: =IF(Z14<>"",Z14,"") -> 5.49 | BG14: 0005731621720 | BH14: 0057316217209 | BM14: CG STRWBRRIES & CREME I/C -NEW | BN14: 1.5 | BO14: LT | BQ14: #N/A | BR14: DNK | BS14: 20 | BT14: 3063.44 | BX14: 7.19 | BY14: 7.19 | BZ14: =BY14-BX14 -> 0 | CC14: =VLOOKUP(A14,'[1]RPT 1280 - Edmonton'!$1:$1048576,4,0) -> #N/A | CE14: EA | CF14: 21.14 | CG14: 0 | CH14: 0 | CI14: 0 | CJ14: =CF14-J14 -> 0 | CK14: =CG14-K14 -> 0 | CL14: =CH14-L14 -> 0 | CM14: =CI14-M14 -> 0
A15: 6500573 | B15: CG VANILLA NSA ICE CREAM -NEW 4 X 1.5 LT | C15: 010513110100 | D15: L M S | E15: A | F15: F | G15: F | J15: =J14 -> 21.14 | O15: =O14 -> 21.14 | P15: =P14 -> 5.285 | Q15: 3 | W15: 1 /4.99 | X15: 5.99 | Z15: 5.49 | AH15: =IF(W15<>"",(RIGHT(W15,LEN(W15)-SEARCH("/",W15,1)))/U15,"") -> #VALUE! | AI15: =IF(X15<>"",X15,"") -> 5.99 | AJ15: =IF(Y15<>"",Y15,"") | AK15: =IF(Z15<>"",Z15,"") -> 5.49 | BG15: 0005731621719 | BH15: 0057316217193 | BM15: CG VANILLA NSA ICE CREAM -NEW | BN15: 1.5 | BO15: LT | BQ15: #N/A | BR15: DNK | BS15: 31 | BT15: 2778.49 | BX15: 7.19 | BY15: 7.19 | BZ15: =BY15-BX15 -> 0 | CC15: =VLOOKUP(A15,'[1]RPT 1280 - Edmonton'!$1:$1048576,4,0) -> #N/A | CE15: EA | CF15: 21.14 | CG15: 0 | CH15: 0 | CI15: 0 | CJ15: =CF15-J15 -> 0 | CK15: =CG15-K15 -> 0 | CL15: =CH15-L15 -> 0 | CM15: =CI15-M15 -> 0
A16: 6500706 | B16: CG VANILLA FROZEN YOGURT -NEW 4 X 1.5 LT | C16: 010513110100 | D16: L M S | E16: A | F16: F | G16: F | J16: =J15 -> 21.14 | O16: =O15 -> 21.14 | P16: =P15 -> 5.285 | Q16: 3 | W16: 1 /4.99 | X16: 5.99 | Z16: 5.49 | AH16: =IF(W16<>"",(RIGHT(W16,LEN(W16)-SEARCH("/",W16,1)))/U16,"") -> #VALUE! | AI16: =IF(X16<>"",X16,"") -> 5.99 | AJ16: =IF(Y16<>"",Y16,"") | AK16: =IF(Z16<>"",Z16,"") -> 5.49 | BG16: 0005731621749 | BH16: 0057316217490 | BM16: CG VANILLA FROZEN YOGURT -NEW | BN16: 1.5 | BO16: LT | BQ16: #N/A | BR16: DNK | BS16: 33 | BT16: 2095.96 | BX16: 7.19 | BY16: 7.19 | BZ16: =BY16-BX16 -> 0 | CC16: =VLOOKUP(A16,'[1]RPT 1280 - Edmonton'!$1:$1048576,4,0) -> #N/A | CE16: EA | CF16: 21.14 | CG16: 0 | CH16: 0 | CI16: 0 | CJ16: =CF16-J16 -> 0 | CK16: =CG16-K16 -> 0 | CL16: =CH16-L16 -> 0 | CM16: =CI16-M16 -> 0
A17: 6500698 | B17: CG HEAVENLY HASH I/CREAM -NEW 4 X 1.5 LT | C17: 010513110100 | D17: L M S | E17: A | F17: F | G17: F | J17: =J16 -> 21.14 | O17: =O16 -> 21.14 | P17: =P16 -> 5.285 | Q17: 3 | W17: 1 /4.99 | X17: 5.99 | Z17: 5.49 | AH17: =IF(W17<>"",(RIGHT(W17,LEN(W17)-SEARCH("/",W17,1)))/U17,"") -> #VALUE! | AI17: =IF(X17<>"",X17,"") -> 5.99 | AJ17: =IF(Y17<>"",Y17,"") | AK17: =IF(Z17<>"",Z17,"") -> 5.49 | BG17: 0005731621724 | BH17: 0057316217247 | BM17: CG HEAVENLY HASH I/CREAM -NEW | BN17: 1.5 | BO17: LT | BQ17: #N/A | BR17: DNK | BS17: 26 | BT17: 3519.2 | BX17: 7.19 | BY17: 7.19 | BZ17: =BY17-BX17 -> 0 | CC17: =VLOOKUP(A17,'[1]RPT 1280 - Edmonton'!$1:$1048576,4,0) -> #N/A | CE17: EA | CF17: 21.14 | CG17: 0 | CH17: 0 | CI17: 0 | CJ17: =CF17-J17 -> 0 | CK17: =CG17-K17 -> 0 | CL17: =CH17-L17 -> 0 | CM17: =CI17-M17 -> 0
A18: 6500664 | B18: CG BUTTERSCTCH CRUNCH I/C -NEW 4 X 1.5 LT | C18: 010513110100 | D18: L M S | E18: A | F18: F | G18: F | J18: =J17 -> 21.14 | O18: =O17 -> 21.14 | P18: =P17 -> 5.285 | Q18: 3 | W18: 1 /4.99 | X18: 5.99 | Z18: 5.49 | AH18: =IF(W18<>"",(RIGHT(W18,LEN(W18)-SEARCH("/",W18,1)))/U18,"") -> #VALUE! | AI18: =IF(X18<>"",X18,"") -> 5.99 | AJ18: =IF(Y18<>"",Y18,"") | AK18: =IF(Z18<>"",Z18,"") -> 5.49 | BG18: 0005731621722 | BH18: 0057316217223 | BM18: CG BUTTERSCTCH CRUNCH I/C -NEW | BN18: 1.5 | BO18: LT | BQ18: #N/A | BR18: DNK | BS18: 19 | BT18: 5243.89 | BX18: 7.19 | BY18: 7.19 | BZ18: =BY18-BX18 -> 0 | CC18: =VLOOKUP(A18,'[1]RPT 1280 - Edmonton'!$1:$1048576,4,0) -> #N/A | CE18: EA | CF18: 21.14 | CG18: 0 | CH18: 0 | CI18: 0 | CJ18: =CF18-J18 -> 0 | CK18: =CG18-K18 -> 0 | CL18: =CH18-L18 -> 0 | CM18: =CI18-M18 -> 0
A19: 6500656 | B19: CG CHOCOLATE EXPLSION I/C -NEW 4 X 1.5 LT | C19: 010513110100 | D19: L M S | E19: A | F19: F | G19: F | J19: =J18 -> 21.14 | O19: =O18 -> 21.14 | P19: =P18 -> 5.285 | Q19: 3 | W19: 1 /4.99 | X19: 5.99 | Z19: 5.49 | AH19: =IF(W19<>"",(RIGHT(W19,LEN(W19)-SEARCH("/",W19,1)))/U19,"") -> #VALUE! | AI19: =IF(X19<>"",X19,"") -> 5.99 | AJ19: =IF(Y19<>"",Y19,"") | AK19: =IF(Z19<>"",Z19,"") -> 5.49 | BG19: 0005731621721 | BH19: 0057316217216 | BM19: CG CHOCOLATE EXPLSION I/C -NEW | BN19: 1.5 | BO19: LT | BQ19: #N/A | BR19: DNK | BS19: 19 | BT19: 4091.36 | BX19: 7.19 | BY19: 7.19 | BZ19: =BY19-BX19 -> 0 | CC19: =VLOOKUP(A19,'[1]RPT 1280 - Edmonton'!$1:$1048576,4,0) -> #N/A | CE19: EA | CF19: 21.14 | CG19: 0 | CH19: 0 | CI19: 0 | CJ19: =CF19-J19 -> 0 | CK19: =CG19-K19 -> 0 | CL19: =CH19-L19 -> 0 | CM19: =CI19-M19 -> 0
A20: 6500714 | B20: CG STRWBRY FROZEN YOGURT -NEW 4 X 1.5 LT | C20: 010513110100 | D20: L M S | E20: A | F20: F | G20: F | J20: =J19 -> 21.14 | O20: =O19 -> 21.14 | P20: =P19 -> 5.285 | Q20: 3 | W20: 1 /4.99 | X20: 5.99 | Z20: 5.49 | AH20: =IF(W20<>"",(RIGHT(W20,LEN(W20)-SEARCH("/",W20,1)))/U20,"") -> #VALUE! | AI20: =IF(X20<>"",X20,"") -> 5.99 | AJ20: =IF(Y20<>"",Y20,"") | AK20: =IF(Z20<>"",Z20,"") -> 5.49 | BG20: 0005731621748 | BH20: 0057316217483 | BM20: CG STRWBRY FROZEN YOGURT -NEW | BN20: 1.5 | BO20: LT | BQ20: #N/A | BR20: DNK | BS20: 37 | BT20: 1266.63 | BX20: 7.19 | BY20: 7.19 | BZ20: =BY20-BX20 -> 0 | CC20: =VLOOKUP(A20,'[1]RPT 1280 - Edmonton'!$1:$1048576,4,0) -> #N/A | CE20: EA | CF20: 21.14 | CG20: 0 | CH20: 0 | CI20: 0 | CJ20: =CF20-J20 -> 0 | CK20: =CG20-K20 -> 0 | CL20: =CH20-L20 -> 0 | CM20: =CI20-M20 -> 0
A21: 6500979 | B21: C.GOLD UNICORN IC POP -Z 4 X 12 EA | C21: 010518110105 | D21: L M S | E21: A | F21: F | G21: F | I21: ALL | J21: 19.86 | O21: 19.86 | P21: 4.965 | Q21: 2 | T21: 1 / $4.99 | U21: 1 | V21: $4.99 | W21: 1 /4.99 | X21: 5.99 | Z21: 5.49 | AA21: 0.032561122 | AC21: 5.99 | AD21: 7.19 | AE21: 6.19 | AF21: 7.19 | AH21: =IF(W21<>"",(RIGHT(W21,LEN(W21)-SEARCH("/",W21,1)))/U21,"") -> 4.99 | AI21: =IF(X21<>"",X21,"") -> 5.99 | AJ21: =IF(Y21<>"",Y21,"") | AK21: =IF(Z21<>"",Z21,"") -> 5.49 | AM21: 19.96 | AN21: 7.6 | AO21: 4 | AP21: =(AM21 * 1.05) - L21 - Q21 - K21 -> 18.958 | AQ21: N | AR21: =(((AH21)-((AP21/AO21) + ((AN21 * 0.03)/AO21)))/AH21)*100 -> 3.8777555 | AS21: =(((AI21)-((AP21/AO21) + ((AN21 * 0.3)/AO21)))/AI21)*100 -> 11.360601 | AT21: =(((AJ21)-((AP21/AO21) + ((AN21 * 0.03)/AO21)))/AJ21)*100 -> #VALUE! | AU21: =(((AK21)-((AP21/AO21) + ((AN21 * 0.07)/AO21)))/AK21)*100 -> 11.247723 | BB21: =(((AH21)-(((AP21/AO21) + ((AN21 * 0.03)/AO21))-AW21))/AH21)*100 -> 3.8777555 | BC21: =(((AI21)-(((AP21/AO21) + ((AN21 * 0.3)/AO21))-AX21))/AI21)*100 -> 11.360601 | BD21: =(((AJ21)-(((AP21/AO21) + ((AN21 * 0.03)/AO21))-AY21))/AJ21)*100 -> #VALUE! | BE21: =(((AK21)-(((AP21/AO21) + ((AN21 * 0.15)/AO21))-AZ21))/AK21)*100 -> 8.4790528 | BG21: 0005731621584 | BH21: 0057316215847 | BJ21: Co-op Gold Ice Cream or Frozen Yogurt 1.5 L or Novelties Package of 4 - 12 | BM21: C.GOLD UNICORN IC POP -Z | BN21: 12 | BO21: EA | BQ21: #N/A | BR21: DNK | BS21: 49 | BT21: 674.89 | BX21: 8.29 | BY21: 7.79 | BZ21: =BY21-BX21 -> -0.5 | CC21: =VLOOKUP(A21,'[1]RPT 1280 - Edmonton'!$1:$1048576,4,0) -> #N/A | CE21: EA | CF21: 19.86 | CG21: 0 | CH21: 0 | CI21: 0 | CJ21: =CF21-J21 -> 0 | CK21: =CG21-K21 -> 0 | CL21: =CH21-L21 -> 0 | CM21: =CI21-M21 -> 0 | CO21: 4.99 | CP21: 4.99 | CQ21: =CP21-CO21 -> 0
A22: 6500680 | B22: CG CHERRIES & CHOC I/CRM -NEW 4 X 1.5 LT | C22: 010513110100 | D22: L M S | E22: A | F22: F | G22: F | I22: ALL | J22: 20.51 | O22: 20.51 | P22: 5.1275 | Q22: 3 | T22: 1 / $4.99 | U22: 1 | V22: $4.99 | W22: 1 /4.99 | X22: 5.99 | Z22: 5.49 | AA22: 0.029427355 | AC22: 5.99 | AD22: 7.19 | AE22: 6.19 | AF22: 7.19 | AH22: =IF(W22<>"",(RIGHT(W22,LEN(W22)-SEARCH("/",W22,1)))/U22,"") -> 4.99 | AI22: =IF(X22<>"",X22,"") -> 5.99 | AJ22: =IF(Y22<>"",Y22,"") | AK22: =IF(Z22<>"",Z22,"") -> 5.49 | AM22: 22.64 | AN22: 8.44 | AO22: 4 | AP22: =(AM22 * 1.05) - L22 - Q22 - K22 -> 20.772 | AQ22: N | AR22: =(((AH22)-((AP22/AO22) + ((AN22 * 0.03)/AO22)))/AH22)*100 -> -5.3366733 | AS22: =(((AI22)-((AP22/AO22) + ((AN22 * 0.3)/AO22)))/AI22)*100 -> 2.7378965 | AT22: =(((AJ22)-((AP22/AO22) + ((AN22 * 0.03)/AO22)))/AJ22)*100 -> #VALUE! | AU22: =(((AK22)-((AP22/AO22) + ((AN22 * 0.07)/AO22)))/AK22)*100 -> 2.71949 | BB22: =(((AH22)-(((AP22/AO22) + ((AN22 * 0.03)/AO22))-AW22))/AH22)*100 -> -5.3366733 | BC22: =(((AI22)-(((AP22/AO22) + ((AN22 * 0.3)/AO22))-AX22))/AI22)*100 -> 2.7378965 | BD22: =(((AJ22)-(((AP22/AO22) + ((AN22 * 0.03)/AO22))-AY22))/AJ22)*100 -> #VALUE! | BE22: =(((AK22)-(((AP22/AO22) + ((AN22 * 0.15)/AO22))-AZ22))/AK22)*100 -> -0.35519126 | BG22: 0005731621723 | BH22: 0057316217230 | BM22: CG CHERRIES & CHOC I/CRM -NEW | BN22: 1.5 | BO22: LT | BQ22: #N/A | BR22: DNK | BX22: 7.19 | BY22: 7.19 | BZ22: =BY22-BX22 -> 0 | CC22: =VLOOKUP(A22,'[1]RPT 1280 - Edmonton'!$1:$1048576,4,0) -> #N/A | CE22: EA | CF22: 20.51 | CG22: 0 | CH22: 0 | CI22: 0 | CJ22: =CF22-J22 -> 0 | CK22: =CG22-K22 -> 0 | CL22: =CH22-L22 -> 0 | CM22: =CI22-M22 -> 0 | CO22: 4.99 | CP22: 4.99 | CQ22: =CP22-CO22 -> 0
A23: 6520761 | B23: CG SSNL CREME BRULEE I/C -Z 4 X 1.5 LT | C23: 010513110107 | D23: L M S | E23: A | F23: F | G23: F | I23: ALL | J23: 22.02 | O23: 22.02 | P23: 5.505 | Q23: 3 | T23: 1 / $4.99 | U23: 1 | V23: $4.99 | W23: 1 /4.99 | X23: 5.99 | Z23: 5.49 | AA23: 0.029616232 | AC23: 5.99 | AD23: 7.19 | AE23: 6.19 | AF23: 7.19 | AH23: =IF(W23<>"",(RIGHT(W23,LEN(W23)-SEARCH("/",W23,1)))/U23,"") -> 4.99 | AI23: =IF(X23<>"",X23,"") -> 5.99 | AJ23: =IF(Y23<>"",Y23,"") | AK23: =IF(Z23<>"",Z23,"") -> 5.49 | AM23: 23.67 | AN23: 6.98 | AO23: 4 | AP23: =(AM23 * 1.05) - L23 - Q23 - K23 -> 21.8535 | AQ23: N | AR23: =(((AH23)-((AP23/AO23) + ((AN23 * 0.03)/AO23)))/AH23)*100 -> -10.535571 | AS23: =(((AI23)-((AP23/AO23) + ((AN23 * 0.3)/AO23)))/AI23)*100 -> 0.052170284 | AT23: =(((AJ23)-((AP23/AO23) + ((AN23 * 0.03)/AO23)))/AJ23)*100 -> #VALUE! | AU23: =(((AK23)-((AP23/AO23) + ((AN23 * 0.07)/AO23)))/AK23)*100 -> -1.7399818 | BB23: =(((AH23)-(((AP23/AO23) + ((AN23 * 0.03)/AO23))-AW23))/AH23)*100 -> -10.535571 | BC23: =(((AI23)-(((AP23/AO23) + ((AN23 * 0.3)/AO23))-AX23))/AI23)*100 -> 0.052170284 | BD23: =(((AJ23)-(((AP23/AO23) + ((AN23 * 0.03)/AO23))-AY23))/AJ23)*100 -> #VALUE! | BE23: =(((AK23)-(((AP23/AO23) + ((AN23 * 0.15)/AO23))-AZ23))/AK23)*100 -> -4.2827869 | BG23: 0005731621845 | BH23: 0057316218459 | BI23: disc-d status | BM23: CG SSNL CREME BRULEE I/C -Z | BN23: 1.5 | BO23: LT | BQ23: #N/A | BR23: DNK | BX23: 7.19 | BY23: 7.19 | BZ23: =BY23-BX23 -> 0 | CC23: =VLOOKUP(A23,'[1]RPT 1280 - Edmonton'!$1:$1048576,4,0) -> #N/A | CE23: EA | CF23: 22.02 | CG23: 0 | CH23: 0 | CI23: 0 | CJ23: =CF23-J23 -> 0 | CK23: =CG23-K23 -> 0 | CL23: =CH23-L23 -> 0 | CM23: =CI23-M23 -> 0 | CO23: 4.99 | CP23: 4.99 | CQ23: =CP23-CO23 -> 0
A24: 6520753 | B24: CG SSNL PUMPKIN CHAI I/C -Z 4 X 1.5 LT | C24: 010513110107 | D24: L M S | E24: A | F24: F | G24: F | J24: =J23 -> 22.02 | O24: =O23 -> 22.02 | P24: =P23 -> 5.505 | Q24: 4 | W24: 1 /4.99 | X24: 5.99 | Z24: 5.49 | AH24: =IF(W24<>"",(RIGHT(W24,LEN(W24)-SEARCH("/",W24,1)))/U24,"") -> #VALUE! | AI24: =IF(X24<>"",X24,"") -> 5.99 | AJ24: =IF(Y24<>"",Y24,"") | AK24: =IF(Z24<>"",Z24,"") -> 5.49 | BG24: 0005731621846 | BH24: 0057316218466 | BM24: CG SSNL PUMPKIN CHAI I/C -Z | BN24: 1.5 | BO24: LT | BQ24: #N/A | BR24: DNK | BX24: 7.19 | BY24: 7.19 | BZ24: =BY24-BX24 -> 0 | CC24: =VLOOKUP(A24,'[1]RPT 1280 - Edmonton'!$1:$1048576,4,0) -> #N/A | CE24: EA | CF24: 22.02 | CG24: 0 | CH24: 0 | CI24: 0 | CJ24: =CF24-J24 -> 0 | CK24: =CG24-K24 -> 0 | CL24: =CH24-L24 -> 0 | CM24: =CI24-M24 -> 0
A25: 6524789 | B25: C.GOLD CHC ALMD I/C BAR 4PK 8 X 4 EA | C25: 010518110106 | D25: L M S | E25: A | F25: F | G25: F | I25: ALL | J25: 37.44 | O25: 37.44 | P25: 4.68 | Q25: 2 | T25: 1 / $4.99 | U25: 1 | V25: $4.99 | W25: 1 /4.99 | X25: 5.99 | Z25: 5.49 | AA25: 0.02909519 | AC25: 5.99 | AD25: 7.19 | AE25: 6.19 | AF25: 7.19 | AH25: =IF(W25<>"",(RIGHT(W25,LEN(W25)-SEARCH("/",W25,1)))/U25,"") -> 4.99 | AI25: =IF(X25<>"",X25,"") -> 5.99 | AJ25: =IF(Y25<>"",Y25,"") | AK25: =IF(Z25<>"",Z25,"") -> 5.49 | AM25: 37.73 | AN25: 5.21 | AO25: 8 | AP25: =(AM25 * 1.05) - L25 - Q25 - K25 -> 37.6165 | AQ25: N | AR25: =(((AH25)-((AP25/AO25) + ((AN25 * 0.03)/AO25)))/AH25)*100 -> 5.3787575 | AS25: =(((AI25)-((AP25/AO25) + ((AN25 * 0.3)/AO25)))/AI25)*100 -> 18.239775 | AT25: =(((AJ25)-((AP25/AO25) + ((AN25 * 0.03)/AO25)))/AJ25)*100 -> #VALUE! | AU25: =(((AK25)-((AP25/AO25) + ((AN25 * 0.07)/AO25)))/AK25)*100 -> 13.521858 | BB25: =(((AH25)-(((AP25/AO25) + ((AN25 * 0.03)/AO25))-AW25))/AH25)*100 -> 5.3787575 | BC25: =(((AI25)-(((AP25/AO25) + ((AN25 * 0.3)/AO25))-AX25))/AI25)*100 -> 18.239775 | BD25: =(((AJ25)-(((AP25/AO25) + ((AN25 * 0.03)/AO25))-AY25))/AJ25)*100 -> #VALUE! | BE25: =(((AK25)-(((AP25/AO25) + ((AN25 * 0.15)/AO25))-AZ25))/AK25)*100 -> 12.57286 | BG25: 0005731621673 | BH25: 0057316216738 | BJ25: Co-op Gold Ice Cream or Frozen Yogurt 1.5 L or Novelties Package of 4 - 12 | BM25: C.GOLD CHC ALMD I/C BAR 4PK | BN25: 4 | BO25: EA | BQ25: #N/A | BR25: DNK | BX25: 7.29 | BY25: 7.29 | BZ25: =BY25-BX25 -> 0 | CC25: =VLOOKUP(A25,'[1]RPT 1280 - Edmonton'!$1:$1048576,4,0) -> #N/A | CE25: EA | CF25: 37.44 | CG25: 0 | CH25: 0 | CI25: 0 | CJ25: =CF25-J25 -> 0 | CK25: =CG25-K25 -> 0 | CL25: =CH25-L25 -> 0 | CM25: =CI25-M25 -> 0 | CO25: 4.99 | CP25: 4.99 | CQ25: =CP25-CO25 -> 0
A26: 6524839 | B26: C.GOLD PRALINE I/C BAR 4PK 8 X 4 EA | C26: 010518110106 | D26: L M S | E26: A | F26: F | G26: F | J26: =J25 -> 37.44 | O26: =O25 -> 37.44 | P26: =P25 -> 4.68 | Q26: 2 | W26: 1 /4.99 | X26: 5.99 | Z26: 5.49 | AH26: =IF(W26<>"",(RIGHT(W26,LEN(W26)-SEARCH("/",W26,1)))/U26,"") -> #VALUE! | AI26: =IF(X26<>"",X26,"") -> 5.99 | AJ26: =IF(Y26<>"",Y26,"") | AK26: =IF(Z26<>"",Z26,"") -> 5.49 | BG26: 0005731621675 | BH26: 0057316216752 | BJ26: Co-op Gold Ice Cream or Frozen Yogurt 1.5 L or Novelties Package of 4 - 12 | BM26: C.GOLD PRALINE I/C BAR 4PK | BN26: 4 | BO26: EA | BQ26: #N/A | BR26: DNK | BX26: 7.29 | BY26: 7.29 | BZ26: =BY26-BX26 -> 0 | CC26: =VLOOKUP(A26,'[1]RPT 1280 - Edmonton'!$1:$1048576,4,0) -> #N/A | CE26: EA | CF26: 37.44 | CG26: 0 | CH26: 0 | CI26: 0 | CJ26: =CF26-J26 -> 0 | CK26: =CG26-K26 -> 0 | CL26: =CH26-L26 -> 0 | CM26: =CI26-M26 -> 0
A27: 6524813 | B27: C.GOLD DARK CHC I/C BAR 4PK 8 X 4 EA | C27: 010518110106 | D27: L M S | E27: A | F27: F | G27: F | J27: =J26 -> 37.44 | O27: =O26 -> 37.44 | P27: =P26 -> 4.68 | Q27: 2 | W27: 1 /4.99 | X27: 5.99 | Z27: 5.49 | AH27: =IF(W27<>"",(RIGHT(W27,LEN(W27)-SEARCH("/",W27,1)))/U27,"") -> #VALUE! | AI27: =IF(X27<>"",X27,"") -> 5.99 | AJ27: =IF(Y27<>"",Y27,"") | AK27: =IF(Z27<>"",Z27,"") -> 5.49 | BG27: 0005731621674 | BH27: 0057316216745 | BJ27: Co-op Gold Ice Cream or Frozen Yogurt 1.5 L or Novelties Package of 4 - 12 | BM27: C.GOLD DARK CHC I/C BAR 4PK | BN27: 4 | BO27: EA | BQ27: #N/A | BR27: DNK | BX27: 7.29 | BY27: 7.29 | BZ27: =BY27-BX27 -> 0 | CC27: =VLOOKUP(A27,'[1]RPT 1280 - Edmonton'!$1:$1048576,4,0) -> #N/A | CE27: EA | CF27: 37.44 | CG27: 0 | CH27: 0 | CI27: 0 | CJ27: =CF27-J27 -> 0 | CK27: =CG27-K27 -> 0 | CL27: =CH27-L27 -> 0 | CM27: =CI27-M27 -> 0
A28: 6524805 | B28: C.GOLD MILK CHOC VAN BAR 4PK 8 X 4 EA | C28: 010518110106 | D28: L M S | E28: A | F28: F | G28: F | I28: ALL | J28: 36.77 | O28: 36.77 | P28: 4.59625 | Q28: 2 | T28: 1 / $4.99 | U28: 1 | V28: $4.99 | W28: 1 /4.99 | X28: 5.99 | Z28: 5.49 | AA28: 0.030994238 | AC28: 5.99 | AD28: 7.19 | AE28: 6.19 | AF28: 7.19 | AH28: =IF(W28<>"",(RIGHT(W28,LEN(W28)-SEARCH("/",W28,1)))/U28,"") -> 4.99 | AI28: =IF(X28<>"",X28,"") -> 5.99 | AJ28: =IF(Y28<>"",Y28,"") | AK28: =IF(Z28<>"",Z28,"") -> 5.49 | AM28: 37.73 | AN28: 5.21 | AO28: 8 | AP28: =(AM28 * 1.05) - L28 - Q28 - K28 -> 37.6165 | AQ28: N | AR28: =(((AH28)-((AP28/AO28) + ((AN28 * 0.03)/AO28)))/AH28)*100 -> 5.3787575 | AS28: =(((AI28)-((AP28/AO28) + ((AN28 * 0.3)/AO28)))/AI28)*100 -> 18.239775 | AT28: =(((AJ28)-((AP28/AO28) + ((AN28 * 0.03)/AO28)))/AJ28)*100 -> #VALUE! | AU28: =(((AK28)-((AP28/AO28) + ((AN28 * 0.07)/AO28)))/AK28)*100 -> 13.521858 | BB28: =(((AH28)-(((AP28/AO28) + ((AN28 * 0.03)/AO28))-AW28))/AH28)*100 -> 5.3787575 | BC28: =(((AI28)-(((AP28/AO28) + ((AN28 * 0.3)/AO28))-AX28))/AI28)*100 -> 18.239775 | BD28: =(((AJ28)-(((AP28/AO28) + ((AN28 * 0.03)/AO28))-AY28))/AJ28)*100 -> #VALUE! | BE28: =(((AK28)-(((AP28/AO28) + ((AN28 * 0.15)/AO28))-AZ28))/AK28)*100 -> 12.57286 | BG28: 0005731621672 | BH28: 0057316216721 | BJ28: Co-op Gold Ice Cream or Frozen Yogurt 1.5 L or Novelties Package of 4 - 12 | BM28: C.GOLD MILK CHOC VAN BAR 4PK | BN28: 4 | BO28: EA | BQ28: #N/A | BR28: DNK | BX28: 7.29 | BY28: 7.29 | BZ28: =BY28-BX28 -> 0 | CC28: =VLOOKUP(A28,'[1]RPT 1280 - Edmonton'!$1:$1048576,4,0) -> #N/A | CE28: EA | CF28: 36.77 | CG28: 0 | CH28: 0 | CI28: 0 | CJ28: =CF28-J28 -> 0 | CK28: =CG28-K28 -> 0 | CL28: =CH28-L28 -> 0 | CM28: =CI28-M28 -> 0 | CO28: 4.99 | CP28: 4.99 | CQ28: =CP28-CO28 -> 0
A29: 6546832 | B29: CG RASPBERRY LEMON SORBET | E29: A | Q29: 2 | W29: 1 /4.99 | X29: 5.99 | Z29: 5.49 | BY29: 7.29 | BZ29: =BY29-BX29 -> 7.29 | CC29: =VLOOKUP(A29,'[1]RPT 1280 - Edmonton'!$1:$1048576,4,0) -> #N/A
A30: 6546840 | B30: CG DRGNFRT MANGO SORBET | E30: A | Q30: 2 | W30: 1 /4.99 | X30: 5.99 | Z30: 5.49 | BY30: 7.29 | BZ30: =BY30-BX30 -> 7.29 | CC30: =VLOOKUP(A30,'[1]RPT 1280 - Edmonton'!$1:$1048576,4,0) -> #N/A
A31: 216713 | B31: FRISKIES CHEF'S BLEND 1 X 7.5 KG | C31: 010132130390 | D31: L M S | E31: D | F31: F | G31: F | I31: E | J31: 21.98 | M31: 4 | O31: 21.98 | P31: 21.98 | Q31: 4 | T31: 1 / $20.99 | U31: 1 | V31: $20.99 | W31: 1/26.99 | X31: 32.99 | Z31: 27.99 | AA31: 0.10080515 | AC31: 25.19 | AD31: 30.19 | AE31: 26.59 | AF31: 28.79 | AH31: =IF(W31<>"",(RIGHT(W31,LEN(W31)-SEARCH("/",W31,1)))/U31,"") -> 26.99 | AI31: =IF(X31<>"",X31,"") -> 32.99 | AJ31: =IF(Y31<>"",Y31,"") | AK31: =IF(Z31<>"",Z31,"") -> 27.99 | AM31: 22.6 | AN31: 16.86 | AO31: 1 | AP31: =(AM31 * 1.05) - L31 - Q31 - K31 -> 19.73 | AQ31: N | AR31: =(((AH31)-((AP31/AO31) + ((AN31 * 0.03)/AO31)))/AH31)*100 -> 25.024824 | AS31: =(((AI31)-((AP31/AO31) + ((AN31 * 0.3)/AO31)))/AI31)*100 -> 24.862079 | AT31: =(((AJ31)-((AP31/AO31) + ((AN31 * 0.03)/AO31)))/AJ31)*100 -> #VALUE! | AU31: =(((AK31)-((AP31/AO31) + ((AN31 * 0.07)/AO31)))/AK31)*100 -> 25.294034 | BB31: =(((AH31)-(((AP31/AO31) + ((AN31 * 0.03)/AO31))-AW31))/AH31)*100 -> 25.024824 | BC31: =(((AI31)-(((AP31/AO31) + ((AN31 * 0.3)/AO31))-AX31))/AI31)*100 -> 24.862079 | BD31: =(((AJ31)-(((AP31/AO31) + ((AN31 * 0.03)/AO31))-AY31))/AJ31)*100 -> #VALUE! | BE31: =(((AK31)-(((AP31/AO31) + ((AN31 * 0.15)/AO31))-AZ31))/AK31)*100 -> 20.47517 | BG31: 0005580022392 | BH31: 0055800223920 | BJ31: Friskies Cat Food 7.26 - 7.5 kg | BM31: FRISKIES CHEF S BLEND | BN31: 7.5 | BO31: KG | BQ31: #N/A | BR31: #N/A | BS31: 26 | BT31: 44923.88 | BV31: 216713 | BX31: 27.49 | BY31: 27.49 | BZ31: =BY31-BX31 -> 0 | CA31: -2.4 | CC31: =VLOOKUP(A31,'[1]RPT 1280 - Edmonton'!$1:$1048576,4,0) -> #N/A | CE31: AA | CF31: 21.98 | CG31: 0 | CH31: 0 | CI31: 4 | CJ31: =CF31-J31 -> 0 | CK31: =CG31-K31 -> 0 | CL31: =CH31-L31 -> 0 | CM31: =CI31-M31 -> 0 | CO31: 20.99 | CP31: 20.99 | CQ31: =CP31-CO31 -> 0
A32: 6240923 | B32: FRISKIES 7 FLAVOUR CAT FD 1 X 7.26 KG | C32: 010132130390 | D32: L M S | E32: D | F32: F | G32: F | I32: S | J32: 21.98 | M32: 4 | O32: 21.98 | P32: 21.98 | Q32: 4 | T32: 1 / $20.99 | U32: 1 | V32: $20.99 | W32: 1/26.99 | X32: 32.99 | Z32: 27.99 | AA32: 0.059483087 | AC32: 25.19 | AD32: 30.19 | AE32: 26.59 | AF32: 28.79 | AH32: =IF(W32<>"",(RIGHT(W32,LEN(W32)-SEARCH("/",W32,1)))/U32,"") -> 26.99 | AI32: =IF(X32<>"",X32,"") -> 32.99 | AJ32: =IF(Y32<>"",Y32,"") | AK32: =IF(Z32<>"",Z32,"") -> 27.99 | AM32: 22.6 | AN32: 16.86 | AO32: 1 | AP32: =(AM32 * 1.05) - L32 - Q32 - K32 -> 19.73 | AQ32: N | AR32: =(((AH32)-((AP32/AO32) + ((AN32 * 0.03)/AO32)))/AH32)*100 -> 25.024824 | AS32: =(((AI32)-((AP32/AO32) + ((AN32 * 0.3)/AO32)))/AI32)*100 -> 24.862079 | AT32: =(((AJ32)-((AP32/AO32) + ((AN32 * 0.03)/AO32)))/AJ32)*100 -> #VALUE! | AU32: =(((AK32)-((AP32/AO32) + ((AN32 * 0.07)/AO32)))/AK32)*100 -> 25.294034 | BB32: =(((AH32)-(((AP32/AO32) + ((AN32 * 0.03)/AO32))-AW32))/AH32)*100 -> 25.024824 | BC32: =(((AI32)-(((AP32/AO32) + ((AN32 * 0.3)/AO32))-AX32))/AI32)*100 -> 24.862079 | BD32: =(((AJ32)-(((AP32/AO32) + ((AN32 * 0.03)/AO32))-AY32))/AJ32)*100 -> #VALUE! | BE32: =(((AK32)-(((AP32/AO32) + ((AN32 * 0.15)/AO32))-AZ32))/AK32)*100 -> 20.47517 | BG32: 0005580024905 | BH32: 0055800249050 | BJ32: Friskies Cat Food 7.26 - 7.5 kg | BM32: FRISKIES 7 FLAVOUR CAT FD | BN32: 7.26 | BO32: KG | BQ32: #N/A | BR32: #N/A | BS32: 29 | BT32: 31146.39 | BV32: 6240923 | BX32: 27.49 | BY32: 27.49 | BZ32: =BY32-BX32 -> 0 | CA32: -2.4 | CC32: =VLOOKUP(A32,'[1]RPT 1280 - Edmonton'!$1:$1048576,4,0) -> #N/A | CE32: AA | CF32: 21.98 | CG32: 0 | CH32: 0 | CI32: 4 | CJ32: =CF32-J32 -> 0 | CK32: =CG32-K32 -> 0 | CL32: =CH32-L32 -> 0 | CM32: =CI32-M32 -> 0 | CO32: 20.99 | CP32: 20.99 | CQ32: =CP32-CO32 -> 0
A33: 6518336 | B33: FRISKIES GRLRS TNDR CRNCY 1 X 7.5 KG | C33: 010132130390 | D33: L M S | E33: D | F33: F | G33: F | I33: C | J33: 21.98 | M33: 4 | O33: 21.98 | P33: 21.98 | Q33: 4 | T33: 1 / $20.99 | U33: 1 | V33: $20.99 | W33: 1/26.99 | X33: 32.99 | Z33: 27.99 | AA33: 0.096822296 | AC33: 25.19 | AD33: 30.19 | AE33: 26.59 | AF33: 28.79 | AH33: =IF(W33<>"",(RIGHT(W33,LEN(W33)-SEARCH("/",W33,1)))/U33,"") -> 26.99 | AI33: =IF(X33<>"",X33,"") -> 32.99 | AJ33: =IF(Y33<>"",Y33,"") | AK33: =IF(Z33<>"",Z33,"") -> 27.99 | AM33: 22.6 | AN33: 16.86 | AO33: 1 | AP33: =(AM33 * 1.05) - L33 - Q33 - K33 -> 19.73 | AQ33: N | AR33: =(((AH33)-((AP33/AO33) + ((AN33 * 0.03)/AO33)))/AH33)*100 -> 25.024824 | AS33: =(((AI33)-((AP33/AO33) + ((AN33 * 0.3)/AO33)))/AI33)*100 -> 24.862079 | AT33: =(((AJ33)-((AP33/AO33) + ((AN33 * 0.03)/AO33)))/AJ33)*100 -> #VALUE! | AU33: =(((AK33)-((AP33/AO33) + ((AN33 * 0.07)/AO33)))/AK33)*100 -> 25.294034 | BB33: =(((AH33)-(((AP33/AO33) + ((AN33 * 0.03)/AO33))-AW33))/AH33)*100 -> 25.024824 | BC33: =(((AI33)-(((AP33/AO33) + ((AN33 * 0.3)/AO33))-AX33))/AI33)*100 -> 24.862079 | BD33: =(((AJ33)-(((AP33/AO33) + ((AN33 * 0.03)/AO33))-AY33))/AJ33)*100 -> #VALUE! | BE33: =(((AK33)-(((AP33/AO33) + ((AN33 * 0.15)/AO33))-AZ33))/AK33)*100 -> 20.47517 | BG33: 0005580019716 | BH33: 0055800197160 | BJ33: Friskies Cat Food 7.26 - 7.5 kg | BM33: FRISKIES GRLRS TNDR CRNCY | BN33: 7.5 | BO33: KG | BQ33: #N/A | BR33: #N/A | BS33: 54 | BT33: 85.98 | BV33: 6518336 | BX33: 27.49 | BY33: 27.49 | BZ33: =BY33-BX33 -> 0 | CC33: =VLOOKUP(A33,'[1]RPT 1280 - Edmonton'!$1:$1048576,4,0) -> #N/A | CE33: AA | CF33: 21.98 | CG33: 0 | CH33: 0 | CI33: 4 | CJ33: =CF33-J33 -> 0 | CK33: =CG33-K33 -> 0 | CL33: =CH33-L33 -> 0 | CM33: =CI33-M33 -> 0 | CO33: 20.99 | CP33: 20.99 | CQ33: =CP33-CO33 -> 0
A34: 6270805 | B34: TIDY CATS GLADE CLR SPR 1 X 5.44 KG | C34: 010134120270 | D34: L M S | E34: D | F34: F | G34: F | I34: ALL | J34: 20.68 | M34: 3 | O34: 20.68 | P34: 20.68 | Q34: 3 | T34: 1 / $20.99 | U34: 1 | V34: $20.99 | W34: 1/26.49 | X34: 30.99 | Z34: 27.49 | AA34: 0.11407337 | AC34: 25.19 | AD34: 30.19 | AE34: 26.59 | AF34: 28.79 | AH34: =IF(W34<>"",(RIGHT(W34,LEN(W34)-SEARCH("/",W34,1)))/U34,"") -> 26.49 | AI34: =IF(X34<>"",X34,"") -> 30.99 | AJ34: =IF(Y34<>"",Y34,"") | AK34: =IF(Z34<>"",Z34,"") -> 27.49 | AM34: 21.19 | AN34: 12 | AO34: 1 | AP34: =(AM34 * 1.05) - L34 - Q34 - K34 -> 19.2495 | AQ34: N | AR34: =(((AH34)-((AP34/AO34) + ((AN34 * 0.03)/AO34)))/AH34)*100 -> 25.973952 | AS34: =(((AI34)-((AP34/AO34) + ((AN34 * 0.3)/AO34)))/AI34)*100 -> 26.268151 | AT34: =(((AJ34)-((AP34/AO34) + ((AN34 * 0.03)/AO34)))/AJ34)*100 -> #VALUE! | AU34: =(((AK34)-((AP34/AO34) + ((AN34 * 0.07)/AO34)))/AK34)*100 -> 26.920698 | BB34: =(((AH34)-(((AP34/AO34) + ((AN34 * 0.03)/AO34))-AW34))/AH34)*100 -> 25.973952 | BC34: =(((AI34)-(((AP34/AO34) + ((AN34 * 0.3)/AO34))-AX34))/AI34)*100 -> 26.268151 | BD34: =(((AJ34)-(((AP34/AO34) + ((AN34 * 0.03)/AO34))-AY34))/AJ34)*100 -> #VALUE! | BE34: =(((AK34)-(((AP34/AO34) + ((AN34 * 0.15)/AO34))-AZ34))/AK34)*100 -> 23.428519 | BG34: 0005580038962 | BH34: 0055800389626 | BJ34: Purina Tidy Cats 5.44 kg | BM34: TIDY CATS GLADE CLR SPR | BN34: 5.44 | BO34: KG | BQ34: #N/A | BR34: #N/A | BS34: 49 | BT34: 2686.59 | BV34: 6270805 | BX34: 28.49 | BY34: 28.49 | BZ34: =BY34-BX34 -> 0 | CC34: =VLOOKUP(A34,'[1]RPT 1280 - Edmonton'!$1:$1048576,4,0) -> #N/A | CE34: AA | CF34: 20.68 | CG34: 0 | CH34: 0 | CI34: 3 | CJ34: =CF34-J34 -> 0 | CK34: =CG34-K34 -> 0 | CL34: =CH34-L34 -> 0 | CM34: =CI34-M34 -> 0 | CO34: 20.99 | CP34: 20.99 | CQ34: =CP34-CO34 -> 0
A35: 6270797 | B35: TIDY CATS 4IN1 LIGHT WT 1 X 5.44 KG | C35: 010134120270 | D35: L M S | E35: D | F35: F | G35: F | J35: =J34 -> 20.68 | M35: 3 | O35: =O34 -> 20.68 | P35: =P34 -> 20.68 | Q35: 3 | W35: 1/26.49 | X35: 30.99 | Z35: 27.49 | AH35: =IF(W35<>"",(RIGHT(W35,LEN(W35)-SEARCH("/",W35,1)))/U35,"") -> #VALUE! | AI35: =IF(X35<>"",X35,"") -> 30.99 | AJ35: =IF(Y35<>"",Y35,"") | AK35: =IF(Z35<>"",Z35,"") -> 27.49 | BG35: 0005580039181 | BH35: 0055800391810 | BJ35: Purina Tidy Cats 5.44 kg | BM35: TIDY CATS 4IN1 LIGHT WT | BN35: 5.44 | BO35: KG | BQ35: #N/A | BR35: #N/A | BS35: 41 | BT35: 11115.49 | BV35: 6270797 | BX35: 28.49 | BY35: 28.49 | BZ35: =BY35-BX35 -> 0 | CC35: =VLOOKUP(A35,'[1]RPT 1280 - Edmonton'!$1:$1048576,4,0) -> #N/A | CE35: AA | CF35: 20.68 | CG35: 0 | CH35: 0 | CI35: 3 | CJ35: =CF35-J35 -> 0 | CK35: =CG35-K35 -> 0 | CL35: =CH35-L35 -> 0 | CM35: =CI35-M35 -> 0
A36: 6270789 | B36: TIDYCATS 24/7 LIGHTWGHT 1 X 5.44 KG | C36: 010134120270 | D36: L M S | E36: D | F36: F | G36: F | J36: =J35 -> 20.68 | M36: 3 | O36: =O35 -> 20.68 | P36: =P35 -> 20.68 | Q36: 3 | W36: 1/26.49 | X36: 30.99 | Z36: 27.49 | AH36: =IF(W36<>"",(RIGHT(W36,LEN(W36)-SEARCH("/",W36,1)))/U36,"") -> #VALUE! | AI36: =IF(X36<>"",X36,"") -> 30.99 | AJ36: =IF(Y36<>"",Y36,"") | AK36: =IF(Z36<>"",Z36,"") -> 27.49 | BG36: 0005580039204 | BH36: 0055800392046 | BJ36: Purina Tidy Cats 5.44 kg | BM36: TIDYCATS 24/7 LIGHTWGHT | BN36: 5.44 | BO36: KG | BQ36: #N/A | BR36: #N/A | BS36: 36 | BT36: 13072.18 | BV36: 6270789 | BX36: 28.49 | BY36: 28.49 | BZ36: =BY36-BX36 -> 0 | CC36: =VLOOKUP(A36,'[1]RPT 1280 - Edmonton'!$1:$1048576,4,0) -> #N/A | CE36: AA | CF36: 20.68 | CG36: 0 | CH36: 0 | CI36: 3 | CJ36: =CF36-J36 -> 0 | CK36: =CG36-K36 -> 0 | CL36: =CH36-L36 -> 0 | CM36: =CI36-M36 -> 0
A37: 786350 | B37: LARABAR APPLE 5PK GF 8 X 225 GR | C37: 010203710120 | D37: L M S | E37: D | F37: F | G37: F | I37: ALL | J37: 56.08 | M37: 6.86 | O37: 56.08 | P37: 7.01 | Q37: 6.86 | T37: 1 / $6.99 | U37: 1 | V37: $6.99 | W37: 1/8.99 | X37: 9.49 | Z37: 8.99 | AA37: 0.060421137 | AC37: 8.49 | AD37: 10.19 | AE37: 8.79 | AF37: 9.59 | AH37: =IF(W37<>"",(RIGHT(W37,LEN(W37)-SEARCH("/",W37,1)))/U37,"") -> 8.99 | AI37: =IF(X37<>"",X37,"") -> 9.49 | AJ37: =IF(Y37<>"",Y37,"") | AK37: =IF(Z37<>"",Z37,"") -> 8.99 | AM37: 56.08 | AN37: 5.11 | AO37: 8 | AP37: =(AM37 * 1.05) - L37 - Q37 - K37 -> 52.024 | AQ37: N | AR37: =(((AH37)-((AP37/AO37) + ((AN37 * 0.03)/AO37)))/AH37)*100 -> 27.450918 | AS37: =(((AI37)-((AP37/AO37) + ((AN37 * 0.3)/AO37)))/AI37)*100 -> 29.456006 | AT37: =(((AJ37)-((AP37/AO37) + ((AN37 * 0.03)/AO37)))/AJ37)*100 -> #VALUE! | AU37: =(((AK37)-((AP37/AO37) + ((AN37 * 0.07)/AO37)))/AK37)*100 -> 27.166713 | BB37: =(((AH37)-(((AP37/AO37) + ((AN37 * 0.03)/AO37))-AW37))/AH37)*100 -> 27.450918 | BC37: =(((AI37)-(((AP37/AO37) + ((AN37 * 0.3)/AO37))-AX37))/AI37)*100 -> 29.456006 | BD37: =(((AJ37)-(((AP37/AO37) + ((AN37 * 0.03)/AO37))-AY37))/AJ37)*100 -> #VALUE! | BE37: =(((AK37)-(((AP37/AO37) + ((AN37 * 0.15)/AO37))-AZ37))/AK37)*100 -> 26.598304 | BG37: 0002190842316 | BH37: 0021908416946 | BM37: LARABAR APPLE 5PK GF | BN37: 225 | BO37: GR | BQ37: #N/A | BR37: D | BS37: 48 | BT37: 3967.49 | BX37: 10.99 | BY37: 10.99 | BZ37: =BY37-BX37 -> 0 | CC37: =VLOOKUP(A37,'[1]RPT 1280 - Edmonton'!$1:$1048576,4,0) -> #N/A | CE37: AA | CF37: 56.08 | CG37: 0 | CH37: 0 | CI37: 6.86 | CJ37: =CF37-J37 -> 0 | CK37: =CG37-K37 -> 0 | CL37: =CH37-L37 -> 0 | CM37: =CI37-M37 -> 0 | CO37: 6.99 | CP37: 6.99 | CQ37: =CP37-CO37 -> 0
A38: 786400 | B38: LARABAR PEA BUT 5PK GF 8 X 240 GR | C38: 010203710120 | D38: L M S | E38: D | F38: F | G38: F | J38: =J37 -> 56.08 | M38: 6.86 | O38: =O37 -> 56.08 | P38: =P37 -> 7.01 | Q38: 6.86 | W38: 1/8.99 | X38: 9.49 | Z38: 8.99 | AH38: =IF(W38<>"",(RIGHT(W38,LEN(W38)-SEARCH("/",W38,1)))/U38,"") -> #VALUE! | AI38: =IF(X38<>"",X38,"") -> 9.49 | AJ38: =IF(Y38<>"",Y38,"") | AK38: =IF(Z38<>"",Z38,"") -> 8.99 | BG38: 0002190842317 | BH38: 0021908416953 | BM38: LARABAR PEA BUT 5PK GF | BN38: 240 | BO38: GR | BQ38: #N/A | BR38: D | BS38: 47 | BT38: 2987.87 | BX38: 10.99 | BY38: 10.99 | BZ38: =BY38-BX38 -> 0 | CC38: =VLOOKUP(A38,'[1]RPT 1280 - Edmonton'!$1:$1048576,4,0) -> #N/A | CE38: AA | CF38: 56.08 | CG38: 0 | CH38: 0 | CI38: 6.86 | CJ38: =CF38-J38 -> 0 | CK38: =CG38-K38 -> 0 | CL38: =CH38-L38 -> 0 | CM38: =CI38-M38 -> 0
A39: 371807 | B39: LARABAR PEA BUT CH CHIP 5PK GF 8 X 225 GR | C39: 010203710120 | D39: L M S | E39: D | F39: F | G39: F | J39: =J38 -> 56.08 | M39: 6.86 | O39: =O38 -> 56.08 | P39: =P38 -> 7.01 | Q39: 6.86 | W39: 1/8.99 | X39: 9.49 | Z39: 8.99 | AH39: =IF(W39<>"",(RIGHT(W39,LEN(W39)-SEARCH("/",W39,1)))/U39,"") -> #VALUE! | AI39: =IF(X39<>"",X39,"") -> 9.49 | AJ39: =IF(Y39<>"",Y39,"") | AK39: =IF(Z39<>"",Z39,"") -> 8.99 | BG39: 0002190846259 | BH39: 0021908462599 | BM39: LARABAR PEA BUT CH CHIP 5PK GF | BN39: 225 | BO39: GR | BQ39: #N/A | BR39: D | BS39: 46 | BT39: 6188.02 | BX39: 10.99 | BY39: 10.99 | BZ39: =BY39-BX39 -> 0 | CC39: =VLOOKUP(A39,'[1]RPT 1280 - Edmonton'!$1:$1048576,4,0) -> #N/A | CE39: AA | CF39: 56.08 | CG39: 0 | CH39: 0 | CI39: 6.86 | CJ39: =CF39-J39 -> 0 | CK39: =CG39-K39 -> 0 | CL39: =CH39-L39 -> 0 | CM39: =CI39-M39 -> 0
A40: 2418051 | B40: LARABAR COCONUT CREAM 5PK GF 8 X 240 GR | C40: 010203710120 | D40: L M S | E40: D | F40: F | G40: F | J40: =J39 -> 56.08 | M40: 6.86 | O40: =O39 -> 56.08 | P40: =P39 -> 7.01 | Q40: 6.86 | W40: 1/8.99 | X40: 9.49 | Z40: 8.99 | AH40: =IF(W40<>"",(RIGHT(W40,LEN(W40)-SEARCH("/",W40,1)))/U40,"") -> #VALUE! | AI40: =IF(X40<>"",X40,"") -> 9.49 | AJ40: =IF(Y40<>"",Y40,"") | AK40: =IF(Z40<>"",Z40,"") -> 8.99 | BG40: 0002190846258 | BH40: 0021908462582 | BM40: LARABAR COCONUT CREAM 5PK GF | BN40: 240 | BO40: GR | BQ40: #N/A | BR40: D | BS40: 48 | BT40: 3171.23 | BX40: 10.99 | BY40: 10.99 | BZ40: =BY40-BX40 -> 0 | CC40: =VLOOKUP(A40,'[1]RPT 1280 - Edmonton'!$1:$1048576,4,0) -> #N/A | CE40: AA | CF40: 56.08 | CG40: 0 | CH40: 0 | CI40: 6.86 | CJ40: =CF40-J40 -> 0 | CK40: =CG40-K40 -> 0 | CL40: =CH40-L40 -> 0 | CM40: =CI40-M40 -> 0
...

Sheet FP - 1
D1: AD NO.: | F1: 15
D2: AD Theme: | F2: we love local
A5: **Remote Market
H6: FLYER START DATE: | L6: 46121 | Q6: FLYER STOP DATE: | T6: =L6+6 -> 46127
A8: 6250120 | B8: str 1.7/kg | N8: produce
A9: Whole Beef Brisket Cut from Canada AA Grade or Higher Random Cryovac Wrapped Raised in Western Canada | M9: =VLOOKUP(M8,Source!$1:$1048576,62,FALSE) -> #N/A
A14: =VLOOKUP(A8,[3]Meat!$1:$1048576,4,0) -> 4960 | M14: =VLOOKUP(M8,Source!$1:$1048576,59,FALSE) -> #N/A
A16: 5.99lb/13.21kg | E16: 6.49lb/14.31kg | I16: 5.99lb/13.21kg | M16: =VLOOKUP(M8,Source!$1:$1048576,23,FALSE) -> #N/A | Q16: =VLOOKUP(M8,Source!$1:$1048576,24,FALSE) -> #N/A | U16: =VLOOKUP(M8,Source!$1:$1048576,26,FALSE) -> #N/A
A18: =VLOOKUP(A8,[4]Source!$1:$1048576,54,FALSE) -> #N/A | E18: =VLOOKUP(A8,[4]Source!$1:$1048576,55,FALSE) -> #N/A | I18: =VLOOKUP(A8,[4]Source!$1:$1048576,57,FALSE) -> #N/A | M18: =VLOOKUP(M8,Source!1:1048576,54,FALSE) -> #N/A | Q18: =VLOOKUP(M8,Source!1:1048576,55,FALSE) -> #N/A | U18: =VLOOKUP(M8,Source!1:1048576,57,FALSE) -> #N/A
A19: 2468312 | B19: red hot april13-14-15-canada | M19: 603605 | N19: Canada-str
A20: Co-op Centsibles Enriched Flour 10 kg | M20: =VLOOKUP(M19,Source!$1:$1048576,62,FALSE) -> Kraft Singles 825 g or Cheez Whiz 900 g
A25: =VLOOKUP(A19,Source!$1:$1048576,59,FALSE) -> 0005731618245 | M25: 0006810089235/6810000359
A27: =VLOOKUP(A19,Source!$1:$1048576,23,FALSE) -> 1 /7.99 | E27: =VLOOKUP(A19,Source!$1:$1048576,24,FALSE) -> 4.99 | I27: =VLOOKUP(A19,Source!$1:$1048576,26,FALSE) -> 9.99 | M27: =VLOOKUP(M19,Source!$1:$1048576,23,FALSE) -> 1 /6.99 | Q27: =VLOOKUP(M19,Source!$1:$1048576,24,FALSE) -> 8.99 | U27: =VLOOKUP(M19,Source!$1:$1048576,26,FALSE) -> 7.99
A29: =VLOOKUP(A19,Source!$1:$1048576,54,FALSE) -> -15.613267 | C29: =VLOOKUP(#REF!,Source!$1:$1048576,54,FALSE) -> #REF! | E29: =VLOOKUP(A19,Source!$1:$1048576,55,FALSE) -> -204.15832 | G29: =VLOOKUP(#REF!,Source!$1:$1048576,54,FALSE) -> #REF! | I29: =VLOOKUP(A19,Source!$1:$1048576,57,FALSE) -> -18.893894 | K29: =VLOOKUP(#REF!,Source!$1:$1048576,54,FALSE) -> #REF! | M29: =VLOOKUP(M19,Source!$1:$1048576,54,FALSE) -> -11.498569 | O29: =VLOOKUP(#REF!,Source!$1:$1048576,54,FALSE) -> #REF! | Q29: =VLOOKUP(M19,Source!$1:$1048576,55,FALSE) -> 4.7219132 | S29: =VLOOKUP(#REF!,Source!$1:$1048576,54,FALSE) -> #REF! | U29: =VLOOKUP(M19,Source!$1:$1048576,57,FALSE) -> -1.8366708 | W29: =VLOOKUP(#REF!,Source!$1:$1048576,54,FALSE) -> #REF!
A30: 6499271 | B30: Canada-str | M30: 856351 | N30: no-str
A31: Co-op Gold Ice Cream or Frozen Yogurt 1.5 L or Novelties Package of 4 - 12 | M31: =VLOOKUP(M30,Source!$1:$1048576,62,FALSE) -> Lucky Dragon AAA Scented Jasmine Rice 18.1 kg
A36: 0005731621715/0005731613225 | M36: =VLOOKUP(M30,Source!$1:$1048576,59,FALSE) -> 0005731616335
A38: =VLOOKUP(A30,Source!$1:$1048576,23,FALSE) -> 1 /4.99 | E38: =VLOOKUP(A30,Source!$1:$1048576,24,FALSE) -> 5.99 | I38: =VLOOKUP(A30,Source!$1:$1048576,26,FALSE) -> 5.49 | M38: =VLOOKUP(M30,Source!$1:$1048576,23,FALSE) -> 1 /27.99 | Q38: =VLOOKUP(M30,Source!$1:$1048576,24,FALSE) -> 59.99 | U38: =VLOOKUP(M30,Source!$1:$1048576,26,FALSE) -> 51.99
A40: =VLOOKUP(A30,Source!$1:$1048576,54,FALSE) -> -4.3947896 | C40: =VLOOKUP(#REF!,Source!$1:$1048576,54,FALSE) -> #REF! | E40: =VLOOKUP(A30,Source!$1:$1048576,55,FALSE) -> 3.0717863 | G40: =VLOOKUP(#REF!,Source!$1:$1048576,54,FALSE) -> #REF! | I40: =VLOOKUP(A30,Source!$1:$1048576,57,FALSE) -> 0.28233151 | K40: =VLOOKUP(#REF!,Source!$1:$1048576,54,FALSE) -> #REF! | M40: =VLOOKUP(M30,Source!$1:$1048576,54,FALSE) -> -23.290461 | O40: =VLOOKUP(#REF!,Source!$1:$1048576,54,FALSE) -> #REF! | Q40: =VLOOKUP(M30,Source!$1:$1048576,55,FALSE) -> 24.51742 | S40: =VLOOKUP(#REF!,Source!$1:$1048576,54,FALSE) -> #REF! | U40: =VLOOKUP(M30,Source!$1:$1048576,57,FALSE) -> 24.41431 | W40: =VLOOKUP(#REF!,Source!$1:$1048576,54,FALSE) -> #REF!
A41: 551002 | M41: 536805 | N41: Canada
A42: Co-op Chicken Split Wings Grain Fed, Free Run, Air Chilled Value Pack Raised in Western Canada | M42: =VLOOKUP(M41,Source!$1:$1048576,62,FALSE) -> Dr. Oetker Pizza Ristorante or Casa Di Mama Frozen 320 - 410 g
A47: 5168 | M47: 0005833617000/0005833617303
A49: 4.99lb/11.00kg | E49: 5.49lb/12.10kg | I49: 5.19lb/11.44kg | M49: =VLOOKUP(M41,Source!$1:$1048576,23,FALSE) -> 1 /3.99 | Q49: =VLOOKUP(M41,Source!$1:$1048576,24,FALSE) -> 4.49 | U49: =VLOOKUP(M41,Source!$1:$1048576,26,FALSE) -> 4.19
A51: =VLOOKUP(A41,Source!$1:$1048576,54,FALSE) -> #N/A | C51: =VLOOKUP(#REF!,Source!$1:$1048576,54,FALSE) -> #REF! | E51: =VLOOKUP(A41,Source!$1:$1048576,55,FALSE) -> #N/A | G51: =VLOOKUP(#REF!,Source!$1:$1048576,54,FALSE) -> #REF! | I51: =VLOOKUP(A41,Source!$1:$1048576,57,FALSE) -> #N/A | K51: =VLOOKUP(#REF!,Source!$1:$1048576,54,FALSE) -> #REF! | M51: =VLOOKUP(M41,Source!$1:$1048576,54,FALSE) -> 1.3816685 | O51: =VLOOKUP(#REF!,Source!$1:$1048576,54,FALSE) -> #REF! | Q51: =VLOOKUP(M41,Source!$1:$1048576,55,FALSE) -> 5.7747375 | S51: =VLOOKUP(#REF!,Source!$1:$1048576,54,FALSE) -> #REF! | U51: =VLOOKUP(M41,Source!$1:$1048576,57,FALSE) -> 2.9509035 | W51: =VLOOKUP(#REF!,Source!$1:$1048576,54,FALSE) -> #REF!

Sheet Meat - P2
A1: 980383
A2: Bone-in Pork Loin Centre Chops Cut In-store by Your Local Butcher Value Pack Raised in Western Canada
A12: =VLOOKUP(A1,[3]Meat!$A:$E,4,0) -> 4725
A14: 3.49lb/7.69kg | I14: 4.49lb/9.90kg | Q14: 3.99lb/8.80kg
A16: =VLOOKUP(A1,[4]Source!$1:$1048576,54,FALSE) -> #N/A | I16: =VLOOKUP(F1,[4]Source!$1:$1048576,55,FALSE) -> #N/A | Q16: =VLOOKUP(A1,[4]Source!$1:$1048576,57,FALSE) -> #N/A
A17: 6250062 | G17: 6250088 | M17: 174177
A18: Boneless Beef Sirloin Tip Roast or Marinating Steak Cut In-store by Your Local Butcher From Canada AA Grade or Higher Aged 14 days Raised in Western Canada | G18: Boneless Stewing Beef Cut In-store by Your Local Butcher from Canada AA Grade or Higher Aged 14 Days Raised in Western Canada | M18: =VLOOKUP(M17,[3]Meat!$1:$1048576,5,0) -> Co-op Boneless Skinless Chicken Breasts Grain Fed, Free Run, Air Chilled Value Pack Raised in Western Canada
A22: 4440/4446 | G22: =VLOOKUP(G17,[3]Meat!$1:$1048576,4,0) -> 4481 | M22: =VLOOKUP(M17,[3]Meat!$1:$1048576,4,0) -> 5146
A24: 9.49lb/20.92kg | C24: 9.99lb/22.02kg | E24: 9.49lb/20.92kg | G24: 10.99lb/24.23kg | I24: 10.99lb/24.23kg | K24: 10.99lb/24.23kg | M24: 5.99lb/13.21kg | Q24: =VLOOKUP(M17,[4]Source!$1:$1048576,24,FALSE) -> #N/A | U24: 6.49lb/14.31kg
A26: =VLOOKUP(A17,[4]Source!$1:$1048576,54,FALSE) -> #N/A | C26: =VLOOKUP(A17,[4]Source!$1:$1048576,55,FALSE) -> #N/A | E26: =VLOOKUP(A17,[4]Source!$1:$1048576,57,FALSE) -> #N/A | F26: =VLOOKUP(F17,[4]Source!$1:$1048576,55,FALSE) -> #N/A | G26: =VLOOKUP(G17,[4]Source!$1:$1048576,54,FALSE) -> #N/A | I26: =VLOOKUP(G17,[4]Source!$1:$1048576,55,FALSE) -> #N/A | K26: =VLOOKUP(G17,[4]Source!$1:$1048576,57,FALSE) -> #N/A | L26: =VLOOKUP(L17,[4]Source!$1:$1048576,55,FALSE) -> #N/A | M26: =VLOOKUP(M17,[4]Source!$1:$1048576,54,FALSE) -> #N/A | Q26: =VLOOKUP(M17,[4]Source!$1:$1048576,55,FALSE) -> #N/A | U26: =VLOOKUP(M17,[4]Source!$1:$1048576,57,FALSE) -> #N/A
A27: 423749 | B27: no | M27: 6220263 | N27: canada | S27: 838441 | T27: canada-str
A28: Johnsonville Dinner Sausage 500 g Select Varieties | M28: =VLOOKUP(M27,[3]Meat!$1:$1048576,5,0) -> Schneiders Smoked Sausage, Juicy Jumbos or All Beef Wieners 375 - 450 g | S28: Harvest Garlic Sausage Ring or Wieners 1 kg
A32: =VLOOKUP(A27,[3]Meat!$1:$1048576,4,0) -> 7778219550 | M32: =VLOOKUP(M27,[3]Meat!$1:$1048576,4,0) -> 6200015806 | S32: 5739370013
A34: 6.49 | E34: 6.99 | I34: 6.79 | M34: 7.99 | O34: 8.99 | Q34: 8.49 | R34: =VLOOKUP(R27,[4]Source!$1:$1048576,24,FALSE) -> #N/A | S34: 14.99 | U34: =VLOOKUP(S27,[4]Source!$1:$1048576,24,FALSE) -> #N/A | W34: 15.49 | X34: =VLOOKUP(X27,[4]Source!$1:$1048576,24,FALSE) -> #N/A
A36: =VLOOKUP(A27,[4]Source!$1:$1048576,54,FALSE) -> #N/A | E36: =VLOOKUP(A27,[4]Source!$1:$1048576,55,FALSE) -> #N/A | I36: =VLOOKUP(A27,[4]Source!$1:$1048576,57,FALSE) -> #N/A | O36: =VLOOKUP(M27,[4]Source!$1:$1048576,55,FALSE) -> #N/A | Q36: =VLOOKUP(M27,[4]Source!$1:$1048576,57,FALSE) -> #N/A | R36: =VLOOKUP(R27,[4]Source!$1:$1048576,55,FALSE) -> #N/A | S36: =VLOOKUP(S27,[4]Source!$1:$1048576,54,FALSE) -> #N/A | U36: =VLOOKUP(S27,[4]Source!$1:$1048576,55,FALSE) -> #N/A | W36: =VLOOKUP(S27,[4]Source!$1:$1048576,57,FALSE) -> #N/A | X36: =VLOOKUP(X27,[4]Source!$1:$1048576,55,FALSE) -> #N/A
A37: 2429140 | B37: canada m5 | G37: 6293278 | H37: canada m4 | M37: 2474310 | N37: canada | S37: 944322 | T37: no
A38: =VLOOKUP(A37,[3]Meat!$1:$1048576,5,0) -> Co-op Gold Pork Back Ribs Fully Cooked 510 - 610 g | G38: =VLOOKUP(G37,[3]Meat!$1:$1048576,5,0) -> Schneiders Lunchmate Stackers or Kits 90 - 120 g | M38: =VLOOKUP(M37,[3]Meat!$1:$1048576,5,0) -> Co-op Gold Potstickers Frozen 454 g | S38: Co-op Centsibles Zesty Chicken Breast 1.13 kg ro Chicken Tenders 1.2 kg Frozen
A42: =VLOOKUP(A37,[3]Meat!$1:$1048576,4,0) -> 5731617819 | G42: =VLOOKUP(G37,[3]Meat!$1:$1048576,4,0) -> 6310032000 | M42: =VLOOKUP(M37,[3]Meat!$1:$1048576,4,0) -> 5731618118 | S42: 5731621865/6731616889
A44: 10.99 | C44: 11.99 | E44: 11.49 | F44: =VLOOKUP(F37,[4]Source!$1:$1048576,24,FALSE) -> #N/A | G44: 3/9.00 | I44: 2/7.00 | K44: 3/9.99 | L44: =VLOOKUP(L37,[4]Source!$1:$1048576,24,FALSE) -> #N/A | M44: 5.49 | O44: 5.99 | Q44: 5.79 | R44: =VLOOKUP(R37,[4]Source!$1:$1048576,24,FALSE) -> #N/A | S44: 16.99 | U44: 16.99 | W44: 16.99 | X44: =VLOOKUP(X37,[4]Source!$1:$1048576,24,FALSE) -> #N/A
A46: =VLOOKUP(A37,[4]Source!$1:$1048576,54,FALSE) -> #N/A | C46: =VLOOKUP(A37,[4]Source!$1:$1048576,55,FALSE) -> #N/A | E46: =VLOOKUP(A37,[4]Source!$1:$1048576,57,FALSE) -> #N/A | F46: =VLOOKUP(F37,[4]Source!$1:$1048576,55,FALSE) -> #N/A | G46: =VLOOKUP(G37,[4]Source!$1:$1048576,54,FALSE) -> #N/A | I46: =VLOOKUP(G37,[4]Source!$1:$1048576,55,FALSE) -> #N/A | K46: =VLOOKUP(G37,[4]Source!$1:$1048576,57,FALSE) -> #N/A | L46: =VLOOKUP(L37,[4]Source!$1:$1048576,55,FALSE) -> #N/A | M46: =VLOOKUP(M37,[4]Source!$1:$1048576,54,FALSE) -> #N/A | O46: =VLOOKUP(M37,[4]Source!$1:$1048576,55,FALSE) -> #N/A | Q46: =VLOOKUP(M37,[4]Source!$1:$1048576,57,FALSE) -> #N/A | R46: =VLOOKUP(R37,[4]Source!$1:$1048576,55,FALSE) -> #N/A | S46: =VLOOKUP(S37,[4]Source!$1:$1048576,54,FALSE) -> #N/A | U46: =VLOOKUP(S37,[4]Source!$1:$1048576,55,FALSE) -> #N/A | W46: =VLOOKUP(S37,[4]Source!$1:$1048576,57,FALSE) -> #N/A | X46: =VLOOKUP(X37,[4]Source!$1:$1048576,55,FALSE) -> #N/A
A47: 860627 | B47: canada m3 | M47: 590125 | N47: canada m 2
A48: =VLOOKUP(A47,[3]Meat!$1:$1048576,5,0) -> Co-op Gold Chicken, Beef or Pork Entrées Frozen 600 - 650 g | M48: =VLOOKUP(M47,[3]Meat!$1:$1048576,5,0) -> Co-op Centsibles Sausage Sticks 300 - 375 g
A58: =VLOOKUP(A47,[3]Meat!$1:$1048576,4,0) -> 5731616262 | M58: =VLOOKUP(M47,[3]Meat!$1:$1048576,4,0) -> 5731617370
A60: 9.99 | E60: 9.99 | I60: 9.99 | M60: 3.99 | Q60: 4.49 | U60: 4.19
A62: =VLOOKUP(A47,[4]Source!$1:$1048576,54,FALSE) -> #N/A | E62: =VLOOKUP(A47,[4]Source!$1:$1048576,55,FALSE) -> #N/A | I62: =VLOOKUP(A47,[4]Source!$1:$1048576,57,FALSE) -> #N/A | M62: =VLOOKUP(M47,[4]Source!$1:$1048576,54,FALSE) -> #N/A | Q62: =VLOOKUP(M47,[4]Source!$1:$1048576,55,FALSE) -> #N/A | U62: =VLOOKUP(M47,[4]Source!$1:$1048576,57,FALSE) -> #N/A
A63: Deli
M64: 124057 | N64: canada
A65: Deli image | M65: =VLOOKUP(M64,[3]Deli!$1:$1048576,5,0) -> Olivieri Pasta 280 - 350 g or Sauce 300 mL
A69: =VLOOKUP(A64,[4]Source!$1:$1048576,59,FALSE) -> #N/A | M69: =VLOOKUP(M64,[3]Deli!$1:$1048576,4,0) -> 5844100138
A71: =VLOOKUP(A64,[4]Source!$1:$1048576,23,FALSE) -> #N/A | E71: =VLOOKUP(A64,[4]Source!$1:$1048576,24,FALSE) -> #N/A | I71: =VLOOKUP(A64,[4]Source!$1:$1048576,26,FALSE) -> #N/A | M71: 5.99 | Q71: 6.49 | U71: 6.49
A73: =VLOOKUP(A64,[4]Source!$1:$1048576,54,FALSE) -> #N/A | E73: =VLOOKUP(A64,[4]Source!$1:$1048576,55,FALSE) -> #N/A | I73: =VLOOKUP(A64,[4]Source!$1:$1048576,57,FALSE) -> #N/A | M73: =VLOOKUP(M64,[4]Source!$1:$1048576,54,FALSE) -> #N/A | Q73: =VLOOKUP(M64,[4]Source!$1:$1048576,55,FALSE) -> #N/A | U73: =VLOOKUP(M64,[4]Source!$1:$1048576,57,FALSE) -> #N/A
A74: 197756 | B74: canada-str | M74: 926766 | N74: canada-str | S74: 682666 | T74: canada-str
A75: =VLOOKUP(A74,[3]Deli!$1:$1048576,5,0) -> The Laughing Cow Spreadable Cheese 128 - 133 g or Dippers Package of 4 Select Varieties | M75: =VLOOKUP(M74,[3]Deli!$1:$1048576,5,0) -> Castello Havarti Cheese 170 - 200 g | S75: =VLOOKUP(S74,[3]Deli!$1:$1048576,5,0) -> Tre Stelle Feta in Brine 200 g
A79: =VLOOKUP(A74,[3]Deli!$1:$1048576,4,0) -> 4175701157 | M79: =VLOOKUP(M74,[3]Deli!$1:$1048576,4,0) -> 6046616100 | S79: =VLOOKUP(S74,[3]Deli!$1:$1048576,4,0) -> 5944100366
A81: 2/6.00 | E81: 4.99 | I81: 2/7.00 | M81: 5.99 | O81: 7.49 | Q81: 5.99 | R81: =VLOOKUP(R74,[4]Source!$1:$1048576,24,FALSE) -> #N/A | S81: 5.99 | U81: 6.99 | W81: 5.99 | X81: =VLOOKUP(X74,[4]Source!$1:$1048576,24,FALSE) -> #N/A
A83: =VLOOKUP(A74,[4]Source!$1:$1048576,54,FALSE) -> #N/A | E83: =VLOOKUP(A74,[4]Source!$1:$1048576,55,FALSE) -> #N/A | I83: =VLOOKUP(A74,[4]Source!$1:$1048576,57,FALSE) -> #N/A | M83: =VLOOKUP(M74,[4]Source!$1:$1048576,54,FALSE) -> #N/A | O83: =VLOOKUP(M74,[4]Source!$1:$1048576,55,FALSE) -> #N/A | Q83: =VLOOKUP(M74,[4]Source!$1:$1048576,57,FALSE) -> #N/A | R83: =VLOOKUP(R74,[4]Source!$1:$1048576,55,FALSE) -> #N/A | S83: =VLOOKUP(S74,[4]Source!$1:$1048576,54,FALSE) -> #N/A | U83: =VLOOKUP(S74,[4]Source!$1:$1048576,55,FALSE) -> #N/A | W83: =VLOOKUP(S74,[4]Source!$1:$1048576,57,FALSE) -> #N/A | X83: =VLOOKUP(X74,[4]Source!$1:$1048576,55,FALSE) -> #N/A

Sheet Fresh - P3
B1: produce
A10: =VLOOKUP(A1,Source!$1:$1048576,59,FALSE) -> #N/A
A12: =VLOOKUP(A1,Source!$1:$1048576,23,FALSE) -> #N/A | I12: =VLOOKUP(A1,Source!$1:$1048576,24,FALSE) -> #N/A | Q12: =VLOOKUP(A1,Source!$1:$1048576,26,FALSE) -> #N/A
A14: =VLOOKUP(A1,Source!$1:$1048576,54,FALSE) -> #N/A | C14: =VLOOKUP(#REF!,Source!$1:$1048576,54,FALSE) -> #REF! | E14: =VLOOKUP(#REF!,Source!$1:$1048576,54,FALSE) -> #REF! | G14: =VLOOKUP(#REF!,Source!$1:$1048576,54,FALSE) -> #REF! | I14: =VLOOKUP(A1,Source!$1:$1048576,55,FALSE) -> #N/A | K14: =VLOOKUP(#REF!,Source!$1:$1048576,55,FALSE) -> #REF! | M14: =VLOOKUP(#REF!,Source!$1:$1048576,55,FALSE) -> #REF! | O14: =VLOOKUP(#REF!,Source!$1:$1048576,55,FALSE) -> #REF! | Q14: =VLOOKUP(A1,Source!$1:$1048576,57,FALSE) -> #N/A | R14: =VLOOKUP(#REF!,Source!#REF!,56,FALSE) -> #REF! | S14: =VLOOKUP(#REF!,Source!$1:$1048576,57,FALSE) -> #REF! | T14: =VLOOKUP(#REF!,Source!#REF!,56,FALSE) -> #REF! | U14: =VLOOKUP(#REF!,Source!$1:$1048576,57,FALSE) -> #REF! | V14: =VLOOKUP(#REF!,Source!#REF!,56,FALSE) -> #REF! | W14: =VLOOKUP(#REF!,Source!$1:$1048576,57,FALSE) -> #REF! | X14: =VLOOKUP(#REF!,Source!#REF!,56,FALSE) -> #REF!
A24: =VLOOKUP(A15,Source!$1:$1048576,59,FALSE) -> #N/A | G24: =VLOOKUP(G15,Source!$1:$1048576,59,FALSE) -> #N/A | M24: =VLOOKUP(M15,Source!$1:$1048576,59,FALSE) -> #N/A | S24: =VLOOKUP(S15,Source!$1:$1048576,59,FALSE) -> #N/A
